Workbook

Sheet Nic
B1: Nic | D1: Aprile | E1: Maggio | F1: Giugno | G1: Luglio | H1: Agosto | I1: Settembre | J1: Ottobre | K1: Novembre | L1: Dicembre | M1: Gennaio | N1: Febbraio | O1: Marzo | P1: Aprile | Q1: Maggio | R1: Giugno | S1: Luglio | T1: Agosto | U1: Settembre | V1: Ottobre | W1: Novembre | X1: Dicembre | Y1: Gennaio | Z1: Febbraio | AA1: Marzo | AB1: Aprile | AC1: Maggio | AD1: Giugno | AE1: Luglio | AF1: Agosto | AG1: Settembre | AH1: Ottobre | AI1: Novembre | AJ1: Dicembre | AK1: Gennaio | AL1: Febbraio | AM1: Marzo | AN1: Aprile | AO1: Maggio | AP1: Giugno | AQ1: Luglio | AR1: Agosto | AS1: Settembre | AT1: Ottobre | AU1: Novembre | AV1: Dicembre | AW1: Gennaio | AX1: Febbraio | AY1: Marzo | AZ1: Aprile | BA1: Maggio | BB1: Giugno | BC1: Luglio | BD1: Agosto | BE1: Settembre | BF1: Ottobre | BG1: Novembre | BH1: Dicembre | BI1: Gennaio | BJ1: Febbraio | BK1: Marzo | BL1: Aprile | BM1: Maggio | BN1: Giugno | BO1: Luglio | BP1: Agosto | BQ1: Settembre | BR1: Ottobre | BS1: Novembre | BT1: Dicembre | BU1: Gennaio | BV1: Febbraio | BW1: Marzo | BX1: Aprile | BY1: Maggio | BZ1: Giugno | CA1: Luglio | CB1: Agosto | CC1: Settembre | CD1: Ottobre | CE1: Novembre | CF1: Dicembre | CG1: Gennaio | CH1: Febbraio | CI1: Marzo | CJ1: Aprile | CK1: Maggio | CL1: Giugno | CM1: Luglio | CN1: Agosto | CO1: Settembre | CP1: Ottobre | CQ1: Novembre | CR1: Dicembre
B2: Anno | D2: 1532 | E2: =D2+IF(E1="Gennaio",1,0) -> 1532 | F2: =E2+IF(F1="Gennaio",1,0) -> 1532 | G2: =F2+IF(G1="Gennaio",1,0) -> 1532 | H2: =G2+IF(H1="Gennaio",1,0) -> 1532 | I2: =H2+IF(I1="Gennaio",1,0) -> 1532 | J2: =I2+IF(J1="Gennaio",1,0) -> 1532 | K2: =J2+IF(K1="Gennaio",1,0) -> 1532 | L2: =K2+IF(L1="Gennaio",1,0) -> 1532 | ... CR2: =CQ2+IF(CR1="Gennaio",1,0) -> 1539
B3: Mese in-game | D3: =C3+1 -> 1 | E3: =D3+1 -> 2 | F3: =E3+1 -> 3 | G3: =F3+1 -> 4 | H3: =G3+1 -> 5 | I3: =H3+1 -> 6 | J3: =I3+1 -> 7 | K3: =J3+1 -> 8 | ... CR3: =CQ3+1 -> 93
E4: attrezzi sake | P4: drip cerimonia | V4: katane | Y4: casetta per associazione pescatori | AH4: barca grande | AK4: molo Takamura
B5: AV | E5: =ABS(E29) -> 150 | P5: =ABS(P43) -> 700 | V5: =ABS(V44) -> 2100 | Y5: =ABS(SUM(Y42:Y45)) -> 6850 | AH5: 6000 | AK5: =ABS(AK35) -> 2500
B6: NAV | D6: =SUM($C5:D5)+D7 -> 5180 | E6: =SUM($C5:E5)+E7 -> 5450 | F6: =SUM($C5:F5)+F7 -> 5720 | G6: =SUM($C5:G5)+G7 -> 5990 | H6: =SUM($C5:H5)+H7 -> 6260 | I6: =SUM($C5:I5)+I7 -> 6530 | J6: =SUM($C5:J5)+J7 -> 6800 | K6: =SUM($C5:K5)+K7 -> 7070 | ... AI6: =SUM($C5:AI5)+AI7 -> 18260 | AJ6: =SUM($C5:AI5)+AJ7 -> 18440 | AK6: =SUM($C5:AJ5)+AK7 -> 18060 | AL6: =SUM($C5:AK5)+AL7 -> 21680 | AM6: =SUM($C5:AL5)+AM7 -> 22800 | AN6: =SUM($C5:AM5)+AN7 -> 23920 | AO6: =SUM($C5:AN5)+AO7 -> 24950 | AP6: =SUM($C5:AO5)+AP7 -> 25980 | AQ6: =SUM($C5:AP5)+AQ7 -> 27010 | ... BW6: =SUM($C5:BV5)+BW7 -> 59970
B7: Liquidi | C7: =SUM(C21:C1048576) -> 5000 | D7: =C7+SUM(D21:D55) -> 5180 | E7: =D7+SUM(E21:E55) -> 5300 | F7: =E7+SUM(F21:F55) -> 5570 | G7: =F7+SUM(G21:G55) -> 5840 | H7: =G7+SUM(H21:H55) -> 6110 | I7: =H7+SUM(I21:I55) -> 6380 | J7: =I7+SUM(J21:J55) -> 6650 | K7: =J7+SUM(K21:K55) -> 6920 | ... BW7: =BV7+SUM(BW21:BW55) -> 41670
B8: Profitto netto | D8: =D7-C7 -> 180 | E8: =E7-D7 -> 120 | F8: =F7-E7 -> 270 | G8: =G7-F7 -> 270 | H8: =H7-G7 -> 270 | I8: =I7-H7 -> 270 | J8: =J7-I7 -> 270 | K8: =K7-J7 -> 270 | ... BW8: =BW7-BV7 -> 1030
A9: Terreni | B9: terreno edificabile a ovest [Kawa] | Y9: 50 | Z9: 50 | AA9: 50 | AB9: 50 | AC9: 50 | AD9: 50 | AE9: 50 | AF9: 50 | AG9: 50 | AH9: 50 | AI9: 50 | AJ9: 50 | AK9: 50 | AL9: 50 | AM9: 50 | AN9: 50 | AO9: 50 | AP9: 50 | AQ9: 50 | AR9: 50 | AS9: 50 | AT9: 50 | AU9: 50 | AV9: 50 | AW9: 50 | AX9: 50 | AY9: 50 | AZ9: 50 | BA9: 50 | BB9: 50 | BC9: 50 | BD9: 50 | BE9: 50 | BF9: 50 | BG9: 50 | BH9: 50 | BI9: 50 | BJ9: 50 | BK9: 50 | BL9: 50 | BM9: 50 | BN9: 50 | BO9: 50 | BP9: 50 | BQ9: 50 | BR9: 50 | BS9: 50 | BT9: 50 | BU9: 50 | BV9: 50 | BW9: 50
A10: Altre tasse | B10: Tassa terreno edificabile | Y10: =-Y9*$A$58 -> -25 | Z10: =-Z9*$A$58 -> -25 | AA10: =-AA9*$A$58 -> -25 | AB10: =-AB9*$A$58 -> -25 | AC10: =-AC9*$A$58 -> -25 | AD10: =-AD9*$A$58 -> -25 | AE10: =-AE9*$A$58 -> -25 | AF10: =-AF9*$A$58 -> -25 | ... BW10: =-BW9*$A$58 -> -25
A11: Barche (unità) | B11: barca grande | AH11: 1 | AI11: 1 | AJ11: 1 | AK11: 1 | AL11: 1 | AM11: 1 | AN11: 1 | AO11: 1 | AP11: 1 | AQ11: 1 | AR11: 1 | AS11: 1 | AT11: 1 | AU11: 1 | AV11: 1 | AW11: 1 | AX11: 1 | AY11: 1 | AZ11: 1 | BA11: 1 | BB11: 1 | BC11: 1 | BD11: 1 | BE11: 1 | BF11: 1 | BG11: 1 | BH11: 1 | BI11: 1 | BJ11: 1 | BK11: 1 | BL11: 1 | BM11: 1 | BN11: 1 | BO11: 1 | BP11: 1 | BQ11: 1 | BR11: 1 | BS11: 1 | BT11: 1 | BU11: 1 | BV11: 1 | BW11: 1
B12: barca media
B13: barca piccola | Y13: 4 | Z13: 4 | AA13: 4 | AB13: 4 | AC13: 4 | AD13: 4 | AE13: 4 | AF13: 4 | AG13: 4 | AH13: 4 | AI13: 4 | AJ13: 4 | AK13: 4 | AL13: 4 | AM13: 4 | AN13: 4 | AO13: 4 | AP13: 4 | AQ13: 4 | AR13: 4 | AS13: 4 | AT13: 4 | AU13: 4 | AV13: 4 | AW13: 4 | AX13: 4 | AY13: 4 | AZ13: 4 | BA13: 4 | BB13: 4 | BC13: 4 | BD13: 4 | BE13: 4 | BF13: 4 | BG13: 4 | BH13: 4 | BI13: 4 | BJ13: 4 | BK13: 4 | BL13: 4 | BM13: 4 | BN13: 4 | BO13: 4 | BP13: 4 | BQ13: 4 | BR13: 4 | BS13: 4 | BT13: 4 | BU13: 4 | BV13: 4 | BW13: 4
A14: Associazione Pescatori | B14: Affitto barche | Y14: =Y11*$A$65+Y12*$A$66+Y13*$A$67 -> 100 | Z14: =Z11*$A$65+Z12*$A$66+Z13*$A$67 -> 100 | AA14: =AA11*$A$65+AA12*$A$66+AA13*$A$67 -> 100 | AB14: =AB11*$A$65+AB12*$A$66+AB13*$A$67 -> 100 | AC14: =AC11*$A$65+AC12*$A$66+AC13*$A$67 -> 100 | AD14: =AD11*$A$65+AD12*$A$66+AD13*$A$67 -> 100 | AE14: =AE11*$A$65+AE12*$A$66+AE13*$A$67 -> 100 | AF14: =AF11*$A$65+AF12*$A$66+AF13*$A$67 -> 100 | ... BW14: =BW11*$A$65+BW12*$A$66+BW13*$A$67 -> 250
B15: Offerte | Y15: 450 | Z15: =Y15-5 -> 445 | AA15: =Z15-5 -> 440 | AB15: =AA15-5 -> 435 | AC15: =AB15-5 -> 430 | AD15: =AC15-5 -> 425 | AE15: =AD15-5 -> 420 | AF15: =AE15-5 -> 415 | AG15: =AF15-5 -> 410 | ... BW15: =BV15-5 -> 200
B16: Assicurazione | Y16: =-(20*Y13+50*Y12+100*Y11) -> -80 | Z16: =-(20*Z13+50*Z12+100*Z11) -> -80 | AA16: =-(20*AA13+50*AA12+100*AA11) -> -80 | AB16: =-(20*AB13+50*AB12+100*AB11) -> -80 | AC16: =-(20*AC13+50*AC12+100*AC11) -> -80 | AD16: =-(20*AD13+50*AD12+100*AD11) -> -80 | AE16: =-(20*AE13+50*AE12+100*AE11) -> -80 | AF16: =-(20*AF13+50*AF12+100*AF11) -> -80 | ... BW16: =-(20*BW13+50*BW12+100*BW11) -> -180
AH17: prelievo Nic | AK17: prelievo Nic
B18: Spese e Movimenti | AH18: =-AH37 -> 0 | AK18: =-1000 -> -1000
B19: totale | X19: 0 | Y19: =X19+SUM(Y14:Y18) -> 470 | Z19: =Y19+SUM(Z14:Z18) -> 935 | AA19: =Z19+SUM(AA14:AA18) -> 1395 | AB19: =AA19+SUM(AB14:AB18) -> 1850 | AC19: =AB19+SUM(AC14:AC18) -> 2300 | AD19: =AC19+SUM(AD14:AD18) -> 2745 | AE19: =AD19+SUM(AE14:AE18) -> 3185 | AF19: =AE19+SUM(AF14:AF18) -> 3620 | ... BW19: =BV19+SUM(BW14:BW18) -> 18695
B21: Cibo | D21: 0 | E21: 0 | F21: 0 | G21: 0 | H21: 0 | I21: 0 | J21: 0 | K21: 0 | L21: 0 | M21: 0 | N21: 0 | O21: 0 | P21: 0 | Q21: 0 | R21: 0 | S21: 0 | T21: 0 | U21: 0 | V21: 0 | W21: 0 | X21: 0 | Y21: 0 | Z21: 0 | AA21: 0 | AB21: 0 | AC21: 0 | AD21: 0 | AE21: 0 | AF21: 0 | AG21: 0 | AH21: 0 | AI21: 0 | AJ21: 0 | AK21: 0 | AL21: 0 | AM21: 0 | AN21: 0 | AO21: 0 | AP21: 0 | AQ21: 0 | AR21: 0 | AS21: 0 | AT21: 0 | AU21: 0 | AV21: 0 | AW21: 0 | AX21: 0 | AY21: 0 | AZ21: 0 | BA21: 0 | BB21: 0 | BC21: 0 | BD21: 0 | BE21: 0 | BF21: 0 | BG21: 0 | BH21: 0 | BI21: 0 | BJ21: 0 | BK21: 0 | BL21: 0 | BM21: 0 | BN21: 0 | BO21: 0 | BP21: 0 | BQ21: 0 | BR21: 0 | BS21: 0 | BT21: 0 | BU21: 0 | BV21: 0 | BW21: 0
B22: Affitto | D22: 0 | E22: 0 | F22: 0 | G22: 0 | H22: 0 | I22: 0 | J22: 0 | K22: 0 | L22: 0 | M22: 0 | N22: 0 | O22: 0 | P22: 0 | Q22: 0 | R22: 0 | S22: 0 | T22: 0 | U22: 0 | V22: 0 | W22: 0 | X22: 0 | Y22: 0 | Z22: 0 | AA22: 0 | AB22: 0 | AC22: 0 | AD22: 0 | AE22: 0 | AF22: 0 | AG22: 0 | AH22: 0 | AI22: 0 | AJ22: 0 | AK22: 0 | AL22: 0 | AM22: 0 | AN22: 0 | AO22: 0 | AP22: 0 | AQ22: 0 | AR22: 0 | AS22: 0 | AT22: 0 | AU22: 0 | AV22: 0 | AW22: 0 | AX22: 0 | AY22: 0 | AZ22: 0 | BA22: 0 | BB22: 0 | BC22: 0 | BD22: 0 | BE22: 0 | BF22: 0 | BG22: 0 | BH22: 0 | BI22: 0 | BJ22: 0 | BK22: 0 | BL22: 0 | BM22: 0 | BN22: 0 | BO22: 0 | BP22: 0 | BQ22: 0 | BR22: 0 | BS22: 0 | BT22: 0 | BU22: 0 | BV22: 0 | BW22: 0
A23: Monaco (impiego)
A24: ⭐️ | B24: Salario da monaco + offerte | D24: =$A$59 -> 180 | E24: =$A$59 -> 180 | F24: =$A$59 -> 180 | G24: =$A$59 -> 180 | H24: =$A$59 -> 180 | I24: =$A$59 -> 180 | J24: =$A$59 -> 180 | K24: =$A$59 -> 180 | ... BW24: =$A$59 -> 180
A25: ⭐️ | B25: Studi monacali
A26: Produzione di sake artigianale (business)
A27: ⭐️ | B27: Artigiano del sake | E27: =$A$60 -> 90 | F27: =$A$60 -> 90 | G27: =$A$60 -> 90 | H27: =$A$60 -> 90 | I27: =$A$60 -> 90 | J27: =$A$60 -> 90 | K27: =$A$60 -> 90 | L27: =$A$60 -> 90 | ... AG27: =$A$60 -> 90 | AK27: =$A$60 -> 90 | AL27: =$A$60 -> 90 | AM27: =$A$60 -> 90 | AN27: =$A$60 -> 90
B28: Vendita al tempio
B29: Attrezzi per il sake | E29: -150
B30: 🔒
A31: Impiegati Barca Grande
A32: 👤 | B32: Capitano | AK32: -1000 | AL32: -1000 | AM32: -1000 | AN32: -1000 | AO32: -1000 | AP32: -1000 | AQ32: -1000 | AR32: -1000 | AS32: -1000 | AT32: -1000 | AU32: -1000 | AV32: -1000 | AW32: -1000 | AX32: -1000 | AY32: -1000 | AZ32: -1000 | BA32: -1000 | BB32: -1000 | BC32: -1000 | BD32: -1000 | BE32: -1000 | BF32: -1000 | BG32: -1000 | BH32: -1000 | BI32: -1000 | BJ32: -1000 | BK32: -1000 | BL32: -1000 | BM32: -1000 | BN32: -1000 | BO32: -1000 | BP32: -1000 | BQ32: -1000 | BR32: -1000 | BS32: -1000 | BT32: -1000 | BU32: -1000 | BV32: -1000 | BW32: -1000
A33: 👤 | B33: Nostromo (samurai) | AK33: -800 | AL33: -800 | AM33: -800 | AN33: -800 | AO33: -800 | AP33: -800 | AQ33: -800 | AR33: -800 | AS33: -800 | AT33: -800 | AU33: -800 | AV33: -800 | AW33: -800 | AX33: -800 | AY33: -800 | AZ33: -800 | BA33: -800 | BB33: -800 | BC33: -800 | BD33: -800 | BE33: -800 | BF33: -800 | BG33: -800 | BH33: -800 | BI33: -800 | BJ33: -800 | BK33: -800 | BL33: -800 | BM33: -800 | BN33: -800 | BO33: -800 | BP33: -800 | BQ33: -800 | BR33: -800 | BS33: -800 | BT33: -800 | BU33: -800 | BV33: -800 | BW33: -800
A34: 👤 | B34: Navigatore | AK34: -700 | AL34: -700 | AM34: -700 | AN34: -700 | AO34: -700 | AP34: -700 | AQ34: -700 | AR34: -700 | AS34: -700 | AT34: -700 | AU34: -700 | AV34: -700 | AW34: -700 | AX34: -700 | AY34: -700 | AZ34: -700 | BA34: -700 | BB34: -700 | BC34: -700 | BD34: -700 | BE34: -700 | BF34: -700 | BG34: -700 | BH34: -700 | BI34: -700 | BJ34: -700 | BK34: -700 | BL34: -700 | BM34: -700 | BN34: -700 | BO34: -700 | BP34: -700 | BQ34: -700 | BR34: -700 | BS34: -700 | BT34: -700 | BU34: -700 | BV34: -700 | BW34: -700
B35: Barca grande e molo (costi e introiti) | AG35: 1 barca grande | AH35: -6000 | AJ35: Molo | AK35: -2500
B36: Profitti vendite | AJ36: Pesca al largo (con volontari) | AK36: 2100 | AL36: 2100 | AM36: 2100 | AN36: 2100 | AO36: 2100 | AP36: 2100 | AQ36: 2100 | AR36: 2100 | AS36: 2100 | AT36: 2100 | AU36: 2100 | AV36: 2100 | AW36: 2100 | AX36: 2100 | AY36: 2100 | AZ36: 2100 | BA36: 2100 | BB36: 2100 | BC36: 2100 | BD36: 2100 | BE36: 2100 | BF36: 2100 | BG36: 2100 | BH36: 2100 | BI36: 2100 | BJ36: 2100 | BK36: 2100 | BL36: 2100 | BM36: 2100 | BN36: 2100 | BO36: 2100 | BP36: 2100 | BQ36: 2100 | BR36: 2100 | BS36: 2100 | BT36: 2100 | BU36: 2100 | BV36: 2100 | BW36: 2100
B37: Movimenti | AJ37: Daimyoo supporto momentaneo | AK37: =ABS(SUM(AK32:AK34))*0.5 -> 1250 | AL37: =ABS(SUM(AL32:AL34))*0.5 -> 1250 | AM37: =ABS(SUM(AM32:AM34))*0.5 -> 1250 | AN37: =ABS(SUM(AN32:AN34))*0.5 -> 1250 | AO37: =ABS(SUM(AO32:AO34))*0.5 -> 1250 | AP37: =ABS(SUM(AP32:AP34))*0.5 -> 1250 | AQ37: =ABS(SUM(AQ32:AQ34))*0.5 -> 1250 | AR37: =ABS(SUM(AR32:AR34))*0.5 -> 1250 | ... BW37: =ABS(SUM(BW32:BW34))*0.5 -> 1250
A38: Hobbies
B39: Tiro con l'arco | U39: premio | V39: 50
A40: ⭐️ | B40: Spada
A42: {=SUM(COUNTIF(A23:A40, {"📜","👤"})) & "/10 Permessi"} -> 3/10 Permessi | C42: Bottino di partenza | P42: drip cerimonia | S42: boost produzione sake | X42: terreno | Y42: =-Y9*40 -> -2000 | AD42: torneo arco | AE42: 400 | AG42: prelievo associazione | AH42: 4000 | AJ42: prelievo associazione | AK42: =-AK18 -> 1000
...

Sheet Cris
B1: Cris | D1: Aprile | E1: Maggio | F1: Giugno | G1: Luglio | H1: Agosto | I1: Settembre | J1: Ottobre | K1: Novembre | L1: Dicembre | M1: Gennaio | N1: Febbraio | O1: Marzo | P1: Aprile | Q1: Maggio | R1: Giugno | S1: Luglio | T1: Agosto | U1: Settembre | V1: Ottobre | W1: Novembre | X1: Dicembre | Y1: Gennaio | Z1: Febbraio | AA1: Marzo | AB1: Aprile | AC1: Maggio | AD1: Giugno | AE1: Luglio | AF1: Agosto | AG1: Settembre | AH1: Ottobre | AI1: Novembre | AJ1: Dicembre | AK1: Gennaio | AL1: Febbraio | AM1: Marzo | AN1: Aprile | AO1: Maggio | AP1: Giugno | AQ1: Luglio | AR1: Agosto | AS1: Settembre | AT1: Ottobre | AU1: Novembre | AV1: Dicembre | AW1: Gennaio | AX1: Febbraio | AY1: Marzo | AZ1: Aprile | BA1: Maggio | BB1: Giugno | BC1: Luglio | BD1: Agosto | BE1: Settembre | BF1: Ottobre | BG1: Novembre | BH1: Dicembre | BI1: Gennaio | BJ1: Febbraio | BK1: Marzo | BL1: Aprile | BM1: Maggio | BN1: Giugno | BO1: Luglio | BP1: Agosto | BQ1: Settembre | BR1: Ottobre | BS1: Novembre | BT1: Dicembre | BU1: Gennaio | BV1: Febbraio | BW1: Marzo | BX1: Aprile | BY1: Maggio | BZ1: Giugno | CA1: Luglio | CB1: Agosto | CC1: Settembre | CD1: Ottobre | CE1: Novembre | CF1: Dicembre | CG1: Gennaio | CH1: Febbraio | CI1: Marzo | CJ1: Aprile | CK1: Maggio | CL1: Giugno | CM1: Luglio | CN1: Agosto | CO1: Settembre | CP1: Ottobre | CQ1: Novembre | CR1: Dicembre
B2: Anno | D2: 1532 | E2: =D2+IF(E1="Gennaio",1,0) -> 1532 | F2: =E2+IF(F1="Gennaio",1,0) -> 1532 | G2: =F2+IF(G1="Gennaio",1,0) -> 1532 | H2: =G2+IF(H1="Gennaio",1,0) -> 1532 | I2: =H2+IF(I1="Gennaio",1,0) -> 1532 | J2: =I2+IF(J1="Gennaio",1,0) -> 1532 | K2: =J2+IF(K1="Gennaio",1,0) -> 1532 | L2: =K2+IF(L1="Gennaio",1,0) -> 1532 | ... CR2: =CQ2+IF(CR1="Gennaio",1,0) -> 1539
B3: Mese in-game | D3: =C3+1 -> 1 | E3: =D3+1 -> 2 | F3: =E3+1 -> 3 | G3: =F3+1 -> 4 | H3: =G3+1 -> 5 | I3: =H3+1 -> 6 | J3: =I3+1 -> 7 | K3: =J3+1 -> 8 | ... CR3: =CQ3+1 -> 93
B5: AV | C5: =ABS(C34) -> 700 | D5: =ABS(D23) -> 35 | E5: =ABS(E18+E19) -> 1020 | AB5: =ABS(AB33+AB34+AB31) -> 8350 | AE5: =-AE31 -> 500
B6: NAV | D6: =SUM($C5:D5)+D7 -> 4235 | E6: =SUM($C5:E5)+E7 -> 4514 | F6: =SUM($C5:F5)+F7 -> 4803 | G6: =SUM($C5:G5)+G7 -> 5156 | H6: =SUM($C5:H5)+H7 -> 5492 | I6: =SUM($C5:I5)+I7 -> 5833 | J6: =SUM($C5:J5)+J7 -> 6147 | K6: =SUM($C5:K5)+K7 -> 6465 | ... BW6: =SUM($C5:BW5)+BW7 -> 55402
B7: Liquidi | C7: =SUM(C11:C1048576) -> 4300 | D7: =C7+SUM(D11:D40) -> 3500 | E7: =D7+SUM(E11:E40) -> 2759 | F7: =E7+SUM(F11:F40) -> 3048 | G7: =F7+SUM(G11:G40) -> 3401 | H7: =G7+SUM(H11:H40) -> 3737 | I7: =H7+SUM(I11:I40) -> 4078 | J7: =I7+SUM(J11:J40) -> 4392 | K7: =J7+SUM(K11:K40) -> 4710 | ... BW7: =BV7+SUM(BW11:BW40) -> 44797
B8: Profitto netto | D8: =D7-C7 -> -800 | E8: =E7-D7 -> -741 | F8: =F7-E7 -> 289 | G8: =G7-F7 -> 353 | H8: =H7-G7 -> 336 | I8: =I7-H7 -> 341 | J8: =J7-I7 -> 314 | K8: =K7-J7 -> 318 | ... BW8: =BW7-BV7 -> 780
A9: Terreni | B9: terreno edificabile a ovest [Kawa] | C9: 100 | D9: 100 | E9: =D9 -> 100 | F9: =E9 -> 100 | G9: =F9 -> 100 | H9: =G9 -> 100 | I9: =H9 -> 100 | J9: =I9 -> 100 | K9: =J9 -> 100 | L9: =K9 -> 100 | ... BW9: =BV9 -> 100
A10: Barche | B10: barca piccola | C10: 1 | D10: 1 | E10: 1 | F10: 1 | G10: 1 | H10: 1 | I10: 1 | J10: 1 | K10: 1 | L10: 1 | M10: 1 | N10: 1 | O10: 1 | P10: 1 | Q10: 1 | R10: 1 | S10: 1 | T10: 1 | U10: 1 | V10: 1 | W10: 1 | X10: 1 | Y10: 1 | Z10: 1 | AA10: 1 | AB10: 1 | AC10: 1 | AD10: 1 | AE10: 1 | AF10: 1 | AG10: 1 | AH10: 1 | AI10: 1 | AJ10: 1 | AK10: 1 | AL10: 1 | AM10: 1 | AN10: 1 | AO10: 1 | AP10: 1 | AQ10: 1 | AR10: 1 | AS10: 1 | AT10: 1 | AU10: 1 | AV10: 1 | AW10: 1 | AX10: 1 | AY10: 1 | AZ10: 1 | BA10: 1 | BB10: 1 | BC10: 1 | BD10: 1 | BE10: 1 | BF10: 1 | BG10: 1 | BH10: 1 | BI10: 1 | BJ10: 1 | BK10: 1 | BL10: 1 | BM10: 1 | BN10: 1 | BO10: 1 | BP10: 1 | BQ10: 1 | BR10: 1 | BS10: 1 | BT10: 1 | BU10: 1 | BV10: 1 | BW10: 1
B11: Cibo | D11: -250 | E11: -250 | F11: -250 | G11: -250 | H11: -250 | I11: -250 | J11: -250 | K11: -250 | L11: -250 | M11: -250 | N11: -250 | O11: -250 | P11: -250 | Q11: -250 | R11: -250 | S11: -250 | T11: -250 | U11: -250 | V11: -250 | W11: -250 | X11: -250 | Y11: -250 | Z11: -250 | AA11: -250 | AB11: -250 | AC11: -250 | AD11: -250 | AE11: -250 | AF11: -250 | AG11: -250 | AH11: -250 | AI11: -250 | AJ11: -250 | AK11: -250 | AL11: -250 | AM11: -250 | AN11: -250 | AO11: -250 | AP11: -250 | AQ11: -250 | AR11: -250 | AS11: -250 | AT11: -250 | AU11: -250 | AV11: -250 | AW11: -250 | AX11: -250 | AY11: -250 | AZ11: -250 | BA11: -250 | BB11: -250 | BC11: -250 | BD11: -250 | BE11: -250 | BF11: -250 | BG11: -250 | BH11: -250 | BI11: -250 | BJ11: -250 | BK11: -250 | BL11: -250 | BM11: -250 | BN11: -250 | BO11: -250 | BP11: -250 | BQ11: -250 | BR11: -250 | BS11: -250 | BT11: -250 | BU11: -250 | BV11: -250 | BW11: -250
B12: Affitto | D12: -50 | E12: -50
A13: Pescatore
B14: Pesca | E14: =$A$41 -> 425 | F14: =$A$41 -> 425 | G14: =$A$41 -> 425 | H14: =$A$41 -> 425 | I14: =$A$41 -> 425 | J14: =$A$41 -> 425 | K14: =$A$41 -> 425 | L14: =$A$41 -> 425 | M14: =$A$43 -> 575 | N14: =$A$43 -> 575 | O14: =$A$43 -> 575 | P14: =$A$43 -> 575 | Q14: =$A$43 -> 575 | R14: =$A$43 -> 575 | S14: =$A$43 -> 575 | T14: =$A$43 -> 575 | ... X14: =$A$43 -> 575
B15: Tassa porto | D15: =-$A$46 -> -20 | E15: =-$A$46 -> -20 | F15: =-$A$46 -> -20 | G15: =-$A$46 -> -20 | H15: =-$A$46 -> -20 | I15: =-$A$46 -> -20 | J15: =-$A$46 -> -20 | K15: =-$A$46 -> -20 | ... BW15: =-$A$46 -> -20
B16: Bancarella
A17: 📜 | B17: Tassa bancarella | D17: =-$A$47 -> -25 | E17: =-$A$47 -> -25 | F17: =-$A$47 -> -25 | G17: =-$A$47 -> -25 | H17: =-$A$47 -> -25 | I17: =-$A$47 -> -25 | J17: =-$A$47 -> -25 | K17: =-$A$47 -> -25 | ... X17: =-$A$47 -> -25
B18: 2 reti da pesca | E18: -20
A19: 📜 | B19: Barca da pesca | D19: barca | E19: -1000
A20: Taglialegna
B21: Taglialegna | E21: 249 | F21: 209 | G21: 243 | H21: 256 | I21: 261 | J21: 234 | K21: 238 | L21: 237
B22: Permesso tagliare legna | D22: 0 | E22: 0 | F22: 0 | G22: 0 | H22: 0 | I22: 0 | J22: 0 | K22: 0 | L22: 0
B23: ascia, machete | D23: -35
A24: Guardia
A25: ⭐️ | B25: guardia allevamento Granchi Kanemura | Y25: 900 | Z25: 900 | AA25: 900 | AB25: 900 | AC25: 900 | AD25: 900 | AE25: 1100 | AF25: 1100 | AG25: 1100 | AH25: 1100 | AI25: 1100 | AJ25: 1100 | AK25: 1100 | AL25: 1100 | AM25: 1100 | AN25: 1100 | AO25: 1100 | AP25: 1100 | AQ25: 1100 | AR25: 1100 | AS25: 1100 | AT25: 1100 | AU25: 1100 | AV25: 1100 | AW25: 1100 | AX25: 1100 | AY25: 1100 | AZ25: 1100 | BA25: 1100 | BB25: 1100 | BC25: 1100 | BD25: 1100 | BE25: 1100 | BF25: 1100 | BG25: 1100 | BH25: 1100 | BI25: 1100 | BJ25: 1100 | BK25: 1100 | BL25: 1100 | BM25: 1100 | BN25: 1100 | BO25: 1100 | BP25: 1100 | BQ25: 1100 | BR25: 1100 | BS25: 1100 | BT25: 1100 | BU25: 1100 | BV25: 1100 | BW25: 1100
A26: Altre tasse | B26: Tassa terreno edificabile | E26: =-$A$45*E9 -> -50 | F26: =-$A$45*F9 -> -50 | G26: =-$A$45*G9 -> -50 | H26: =-$A$45*H9 -> -50 | I26: =-$A$45*I9 -> -50 | J26: =-$A$45*J9 -> -50 | K26: =-$A$45*K9 -> -50 | L26: =-$A$45*L9 -> -50 | ... BW26: =-$A$45*BW9 -> -50
A29: {=SUM(COUNTIF(A13:A25, {"📜","👤"})) & "/10 Permessi"} -> 2/10 Permessi
C30: Bottino di partenza | AJ30: missione | AK30: 150
C31: 5000 | AA31: Casa a nord-est | AB31: =-6000-1500-500 -> -8000 | AD31: katana 931 | AE31: -500
C33: 100 Kawa di terreno boschivo non-edificabile | D33: artigiano per costruire la casetta | G33: consegna casse | O33: samurai | X33: piccolo lingotto d'oro | AA33: Armatura da samurai | AB33: -300 | AD33: scatola del relitto | AE33: 300
C34: =-700 -> -700 | D34: -400 | G34: 30 | O34: 300 | X34: specchio da viaggio finemente decorato | AA34: 2 completi vestiti | AB34: -50 | AD34: piccolo lingotto | AE34: 3500
X35: Maschera da Cerimonia bianca finemente decorata
D36: bonifica bosco | O36: vende perle | AD36: mancia di netsuki | AE36: 30
D37: -20 | O37: =100 * 5 * 6 -> 3000
A41: 425 | B41: Pescatore (barca piccola)
A42: 500 | B42: Pescatore (barca media)
A43: 575 | B43: Pescatore (barca grande)
A44: 240 | B44: Taglialegna
A45: 0.5 | B45: tassa terreno edificabile $/kawa
A46: 20 | B46: Tassa porto
A47: 25 | B47: Tassa bancarella

Sheet Peter
B1: Peter | D1: Aprile | E1: Maggio | F1: Giugno | G1: Luglio | H1: Agosto | I1: Settembre | J1: Ottobre | K1: Novembre | L1: Dicembre | M1: Gennaio | N1: Febbraio | O1: Marzo | P1: Aprile | Q1: Maggio | R1: Giugno | S1: Luglio | T1: Agosto | U1: Settembre | V1: Ottobre | W1: Novembre | X1: Dicembre | Y1: Gennaio | Z1: Febbraio | AA1: Marzo | AB1: Aprile | AC1: Maggio | AD1: Giugno | AE1: Luglio | AF1: Agosto | AG1: Settembre | AH1: Ottobre | AI1: Novembre | AJ1: Dicembre | AK1: Gennaio | AL1: Febbraio | AM1: Marzo | AN1: Aprile | AO1: Maggio | AP1: Giugno | AQ1: Luglio | AR1: Agosto | AS1: Settembre | AT1: Ottobre | AU1: Novembre | AV1: Dicembre | AW1: Gennaio | AX1: Febbraio | AY1: Marzo | AZ1: Aprile | BA1: Maggio | BB1: Giugno | BC1: Luglio | BD1: Agosto | BE1: Settembre | BF1: Ottobre | BG1: Novembre | BH1: Dicembre | BI1: Gennaio | BJ1: Febbraio | BK1: Marzo | BL1: Aprile | BM1: Maggio | BN1: Giugno | BO1: Luglio | BP1: Agosto | BQ1: Settembre | BR1: Ottobre | BS1: Novembre | BT1: Dicembre | BU1: Gennaio | BV1: Febbraio | BW1: Marzo | BX1: Aprile | BY1: Maggio | BZ1: Giugno | CA1: Luglio | CB1: Agosto | CC1: Settembre | CD1: Ottobre | CE1: Novembre | CF1: Dicembre | CG1: Gennaio | CH1: Febbraio | CI1: Marzo | CJ1: Aprile | CK1: Maggio | CL1: Giugno | CM1: Luglio | CN1: Agosto | CO1: Settembre | CP1: Ottobre | CQ1: Novembre | CR1: Dicembre
B2: Anno | D2: 1532 | E2: =D2+IF(E1="Gennaio",1,0) -> 1532 | F2: =E2+IF(F1="Gennaio",1,0) -> 1532 | G2: =F2+IF(G1="Gennaio",1,0) -> 1532 | H2: =G2+IF(H1="Gennaio",1,0) -> 1532 | I2: =H2+IF(I1="Gennaio",1,0) -> 1532 | J2: =I2+IF(J1="Gennaio",1,0) -> 1532 | K2: =J2+IF(K1="Gennaio",1,0) -> 1532 | L2: =K2+IF(L1="Gennaio",1,0) -> 1532 | ... CR2: =CQ2+IF(CR1="Gennaio",1,0) -> 1539
B3: Mese in-game | D3: =C3+1 -> 1 | E3: =D3+1 -> 2 | F3: =E3+1 -> 3 | G3: =F3+1 -> 4 | H3: =G3+1 -> 5 | I3: =H3+1 -> 6 | J3: =I3+1 -> 7 | K3: =J3+1 -> 8 | ... CR3: =CQ3+1 -> 93
AH4: todo increase income | AN4: =SUMIF(AN11:AN39, ">=0") -> 4334
B5: AV | C5: =ABS(C46) -> 230 | D5: =ABS(D16+D46) -> 1400 | G5: =ABS(G20) -> 900 | J5: =ABS(J24) -> 900 | M5: =ABS(M32+M46) -> 5120 | Y5: =-Y28 -> 2700 | AG5: =ABS(SUM(Y48:AG48)) -> 27500
B6: NAV | D6: =SUM($C5:D5)+D7 -> 5427 | E6: =SUM($C5:E5)+E7 -> 5914 | F6: =SUM($C5:F5)+F7 -> 6401 | G6: =SUM($C5:G5)+G7 -> 7133.2 | H6: =SUM($C5:H5)+H7 -> 7865.4 | I6: =SUM($C5:I5)+I7 -> 8597.6 | J6: =SUM($C5:J5)+J7 -> 9600 | K6: =SUM($C5:K5)+K7 -> 11602.4 | ... AA6: =SUM($C5:AA5)+AA7 -> 20635.133 | AB6: =SUM($C5:AA5)+AB7 -> 19280.658 | AC6: =SUM($C5:AC5)+AC7 -> 18026.182 | AD6: =SUM($C5:AD5)+AD7 -> 16771.707 | AE6: =SUM($C5:AD5)+AE7 -> 15115.131 | AF6: =SUM($C5:AF5)+AF7 -> 13158.556 | AG6: =SUM($C5:AG5)+AG7 -> 38751.98 | AH6: =SUM($C5:AH5)+AH7 -> 39675.96 | AI6: =SUM($C5:AI5)+AI7 -> 40014.94 | AJ6: =SUM($C5:AJ5)+AJ7 -> 40623.92 | AK6: =SUM($C5:AK5)+AK7 -> 41284.9 | AL6: =SUM($C5:AL5)+AL7 -> 41947.88 | AM6: =SUM($C5:AM5)+AM7 -> 42662.86 | ... BW6: =SUM($C5:BW5)+BW7 -> 71484.14
B7: Liquidi | C7: =SUM(C9:C1048576) -> 4770 | D7: =C7+SUM(D9:D1048576) -> 3797 | E7: =D7+SUM(E9:E1048576) -> 4284 | F7: =E7+SUM(F9:F1048576) -> 4771 | G7: =F7+SUM(G9:G1048576) -> 4603.2 | H7: =G7+SUM(H9:H1048576) -> 5335.4 | I7: =H7+SUM(I9:I1048576) -> 6067.6 | J7: =I7+SUM(J9:J1048576) -> 6170 | K7: =J7+SUM(K9:K1048576) -> 8172.4 | ... BW7: =BV7+SUM(BW9:BW1048576) -> 32734.14
B8: Profitto netto | D8: =D7-C7 -> -973 | E8: =E7-D7 -> 487 | F8: =F7-E7 -> 487 | G8: =G7-F7 -> -167.8 | H8: =H7-G7 -> 732.2 | I8: =I7-H7 -> 732.2 | J8: =J7-I7 -> 102.4 | K8: =K7-J7 -> 2002.4 | ... BW8: =BW7-BV7 -> 836.98
B9: Cibo | D9: -270 | E9: -270 | F9: -270 | G9: -270 | H9: -270 | I9: -270 | J9: -270 | K9: -270 | L9: -270 | M9: -270 | N9: -270 | O9: -270 | P9: -270 | Q9: -270 | R9: -270 | S9: -270 | T9: -270 | U9: -270 | V9: -270 | W9: -270 | X9: -270 | Y9: -270 | Z9: -270 | AA9: -270 | AB9: -270 | AC9: -270 | AD9: -270 | AE9: -270 | AF9: -270 | AG9: -270 | AH9: -270 | AI9: -270 | AJ9: -270 | AK9: -270 | AL9: -270 | AM9: -270 | AN9: -270 | AO9: -270 | AP9: -270 | AQ9: -270 | AR9: -270 | AS9: -270 | AT9: -270 | AU9: -270 | AV9: -270 | AW9: -270 | AX9: -270 | AY9: -270 | AZ9: -270 | BA9: -270 | BB9: -270 | BC9: -270 | BD9: -270 | BE9: -270 | BF9: -270 | BG9: -270 | BH9: -270 | BI9: -270 | BJ9: -270 | BK9: -270 | BL9: -270 | BM9: -270 | BN9: -270 | BO9: -270 | BP9: -270 | BQ9: -270 | BR9: -270 | BS9: -270 | BT9: -270 | BU9: -270 | BV9: -270 | BW9: -270
B10: Affitto | D10: -160 | E10: -160 | F10: -160 | G10: -160 | H10: -160 | I10: -160 | J10: -160 | K10: -160 | L10: -160 | M10: -160 | N10: -160 | O10: -160 | P10: -160 | Q10: -160 | R10: -160 | S10: -160 | T10: -160 | U10: -160 | V10: -160 | W10: -160 | X10: -160 | Y10: -160 | Z10: -160 | AA10: -160 | AB10: -160 | AC10: -160 | AD10: -160 | AE10: -160 | AF10: -160 | AG10: -160 | AH10: -160 | AI10: -160 | AJ10: -160 | AK10: -160 | AL10: -160 | AM10: -160 | AN10: -160 | AO10: -160 | AP10: -160 | AQ10: -160 | AR10: -160 | AS10: -160 | AT10: -160 | AU10: -160 | AV10: -160 | AW10: -160 | AX10: -160 | AY10: -160 | AZ10: -160 | BA10: -160 | BB10: -160 | BC10: -160 | BD10: -160 | BE10: -160 | BF10: -160 | BG10: -160 | BH10: -160 | BI10: -160 | BJ10: -160 | BK10: -160 | BL10: -160 | BM10: -160 | BN10: -160 | BO10: -160 | BP10: -160 | BQ10: -160 | BR10: -160 | BS10: -160 | BT10: -160 | BU10: -160 | BV10: -160 | BW10: -160
A11: Tratta 1 (K-H-T) | D11: =$A$53 -> 1100 | E11: =$A$53 -> 1100 | F11: =$A$53 -> 1100 | G11: =$A$53 -> 1100 | H11: =$A$53 -> 1100 | I11: =$A$53 -> 1100 | J11: =$A$53 -> 1100 | K11: =$A$53 -> 1100 | ... BW11: =$A$53 -> 1100
A12: 📜 | B12: Tassa rotta commerciale | D12: =-$A$60 -> -100 | E12: =-$A$60 -> -100 | F12: =-$A$60 -> -100 | G12: =-$A$60 -> -100 | H12: =-$A$60 -> -100 | I12: =-$A$60 -> -100 | J12: =-$A$60 -> -100 | K12: =-$A$60 -> -100 | ... BW12: =-$A$60 -> -100
A13: ⭐️ | B13: Mercante (Peter)
A14: 👤 | B14: Apprendista mercante | S14: =$A$53*$A$55 -> 660 | T14: =$A$53*$A$55 -> 660 | U14: =$A$53*$A$55 -> 660 | V14: =$A$53*$A$55 -> 660 | W14: =$A$53*$A$55 -> 660 | X14: =$A$53*$A$55 -> 660 | Y14: =$A$53*$A$55 -> 660 | Z14: =$A$53*$A$55 -> 660 | ... BW14: =$A$53*$A$55 -> 660
B15: salario | S15: =-$A$54 -> -270 | T15: =-$A$54 -> -270 | U15: =-$A$54 -> -270 | V15: =-$A$54 -> -270 | W15: =-$A$54 -> -270 | X15: =-$A$54 -> -270 | Y15: =-$A$54 -> -270 | Z15: =-$A$54 -> -270 | ... AD15: =-$A$54 -> -270 | AE15: -400 | AF15: -400 | AG15: -400 | AH15: -440 | AI15: -480 | AJ15: -520 | AK15: -520 | AL15: -520 | AM15: -520 | AN15: -520 | AO15: -520 | AP15: -520 | AQ15: -520 | AR15: -520 | AS15: -520 | AT15: -520 | AU15: -520 | AV15: -520 | AW15: -520 | AX15: -520 | AY15: -520 | AZ15: -520 | BA15: -520 | BB15: -520 | BC15: -520 | BD15: -520 | BE15: -520 | BF15: -520 | BG15: -520 | BH15: -520 | BI15: -520 | BJ15: -520 | BK15: -520 | BL15: -520 | BM15: -520 | BN15: -520 | BO15: -520 | BP15: -520 | BQ15: -520 | BR15: -520 | BS15: -520 | BT15: -520 | BU15: -520 | BV15: -520 | BW15: -520
B16: Carro, cavallo, barili | D16: -900 | AN16: todo boost profitti Hirata
A17: Tratta 2 (U-H-K) | G17: =$A$53*$A$55 -> 660 | H17: =$A$53*$A$55 -> 660 | I17: =$A$53*$A$55 -> 660 | J17: =$A$53*$A$55 -> 660 | K17: =$A$53*$A$55 -> 660 | L17: =$A$53*$A$55 -> 660 | M17: =$A$53*$A$55 -> 660 | N17: =$A$53*$A$55 -> 660 | ... BW17: =$A$53*$A$55 -> 660
A18: 📜 | B18: Tassa rotta commerciale | G18: =- $A$60 -> -100 | H18: =- $A$60 -> -100 | I18: =- $A$60 -> -100 | J18: =- $A$60 -> -100 | K18: =- $A$60 -> -100 | L18: =- $A$60 -> -100 | M18: =- $A$60 -> -100 | N18: =- $A$60 -> -100 | ... BW18: =- $A$60 -> -100
A19: 👤 | B19: Apprendista mercante | G19: =-$A$54 -> -270 | H19: =-$A$54 -> -270 | I19: =-$A$54 -> -270 | J19: =-$A$54 -> -270 | K19: =-$A$54 -> -270 | L19: =-$A$54 -> -270 | M19: =-$A$54 -> -270 | N19: =-$A$54 -> -270 | ... AD19: =-$A$54 -> -270 | AE19: -400 | AF19: -400 | AG19: -400 | AH19: -440 | AI19: -480 | AJ19: -520 | AK19: -520 | AL19: -520 | AM19: -520 | AN19: -520 | AO19: -520 | AP19: -520 | AQ19: -520 | AR19: -520 | AS19: -520 | AT19: -520 | AU19: -520 | AV19: -520 | AW19: -520 | AX19: -520 | AY19: -520 | AZ19: -520 | BA19: -520 | BB19: -520 | BC19: -520 | BD19: -520 | BE19: -520 | BF19: -520 | BG19: -520 | BH19: -520 | BI19: -520 | BJ19: -520 | BK19: -520 | BL19: -520 | BM19: -520 | BN19: -520 | BO19: -520 | BP19: -520 | BQ19: -520 | BR19: -520 | BS19: -520 | BT19: -520 | BU19: -520 | BV19: -520 | BW19: -520
B20: Carro, cavallo, barili | G20: -900
A21: Tratta 3 (T-H-K) | J21: =$A$53*$A$55 -> 660 | K21: =$A$53*$A$55 -> 660 | L21: =$A$53*$A$55 -> 660 | M21: =$A$53*$A$55 -> 660 | N21: =$A$53*$A$55 -> 660 | O21: =$A$53*$A$55 -> 660 | P21: =$A$53*$A$55 -> 660 | Q21: =$A$53*$A$55 -> 660 | ... BW21: =$A$53*$A$55 -> 660
A22: 📜 | B22: Tassa rotta commerciale | J22: =- $A$60 -> -100 | K22: =- $A$60 -> -100 | L22: =- $A$60 -> -100 | M22: =- $A$60 -> -100 | N22: =- $A$60 -> -100 | O22: =- $A$60 -> -100 | P22: =- $A$60 -> -100 | Q22: =- $A$60 -> -100 | ... BW22: =- $A$60 -> -100
A23: 👤 | B23: Apprendista mercante | J23: =-$A$54 -> -270 | K23: =-$A$54 -> -270 | L23: =-$A$54 -> -270 | M23: =-$A$54 -> -270 | N23: =-$A$54 -> -270 | O23: =-$A$54 -> -270 | P23: =-$A$54 -> -270 | Q23: =-$A$54 -> -270 | ... AD23: =-$A$54 -> -270 | AE23: -400 | AF23: -400 | AG23: -400 | AH23: -440 | AI23: -480 | AJ23: -520 | AK23: -519 | AL23: -518 | AM23: -517 | AN23: -516 | AO23: -515 | AP23: -514 | AQ23: -513 | AR23: -512 | AS23: -511 | AT23: -510 | AU23: -509 | AV23: -508 | AW23: -507 | AX23: -506 | AY23: -505 | AZ23: -504 | BA23: -503 | BB23: -502 | BC23: -501 | BD23: -500 | BE23: -499 | BF23: -498 | BG23: -497 | BH23: -496 | BI23: -495 | BJ23: -494 | BK23: -493 | BL23: -492 | BM23: -491 | BN23: -490 | BO23: -489 | BP23: -488 | BQ23: -487 | BR23: -486 | BS23: -485 | BT23: -484 | BU23: -483 | BV23: -482 | BW23: -481
B24: Carro, cavallo, barili | J24: -900
A25: Tratta 4 Marittima (T-H-K) | Y25: =$A$61 -> 700 | Z25: =$A$61 -> 700 | AA25: =$A$61 -> 700 | AB25: =$A$61 -> 700 | AC25: =$A$61 -> 700 | AD25: =$A$61 -> 700 | AE25: =$A$61*1.1 -> 770 | AF25: =$A$61*1.1 -> 770 | AG25: =$A$61*1.1 -> 770 | AH25: =$A$61*1.1 -> 770 | AI25: =$A$61*1.1 -> 770 | AJ25: =$A$61*1.1 -> 770 | AK25: =$A$61*1.1 -> 770 | AL25: =$A$61*1.1 -> 770 | ... BW25: =$A$61*1.1 -> 770
A26: 📜 | B26: Tassa rotta commerciale (barca media) | Y26: =- $A$60 -> -100 | Z26: =- $A$60 -> -100 | AA26: =- $A$60 -> -100 | AB26: =- $A$60 -> -100 | AC26: =- $A$60 -> -100 | AD26: =- $A$60 -> -100 | AE26: =- $A$60 -> -100 | AF26: =- $A$60 -> -100 | ... BW26: =- $A$60 -> -100
A27: 👤 | B27: Apprendista mercante | Y27: =-$A$54 -> -270 | Z27: =-$A$54 -> -270 | AA27: =-$A$54 -> -270 | AB27: =-$A$54 -> -270 | AC27: =-$A$54 -> -270 | AD27: =-$A$54 -> -270 | AE27: -400 | AF27: -400 | AG27: -400 | AH27: -440 | AI27: -480 | AJ27: -520 | AK27: -520 | AL27: -520 | AM27: -520 | AN27: -520 | AO27: -520 | AP27: -520 | AQ27: -520 | AR27: -520 | AS27: -520 | AT27: -520 | AU27: -520 | AV27: -520 | AW27: -520 | AX27: -520 | AY27: -520 | AZ27: -520 | BA27: -520 | BB27: -520 | BC27: -520 | BD27: -520 | BE27: -520 | BF27: -520 | BG27: -520 | BH27: -520 | BI27: -520 | BJ27: -520 | BK27: -520 | BL27: -520 | BM27: -520 | BN27: -520 | BO27: -520 | BP27: -520 | BQ27: -520 | BR27: -520 | BS27: -520 | BT27: -520 | BU27: -520 | BV27: -520 | BW27: -520
B28: Barca e attrezzi | Y28: -2700
A29: Magazzino piccolo a Hakusui (rotte 1, 2, 3)
A30: 📜 | B30: Boost vendite | M30: =(M11+M17+M21)*$A$56 -> 484 | N30: =(N11+N17+N21)*$A$56 -> 484 | O30: =(O11+O17+O21)*$A$56 -> 484 | P30: =(P11+P17+P21)*$A$56 -> 484 | Q30: =(Q11+Q17+Q21)*$A$56 -> 484 | R30: =(R11+R17+R21)*$A$56 -> 484 | S30: =(S11+S17+S21)*$A$56 -> 484 | T30: =(T11+T17+T21)*$A$56 -> 484 | ... BW30: =(BW11+BW17+BW21)*$A$56 -> 484
A31: 👤 | B31: Mantenimento | M31: =-$A$58 -> -350 | N31: =-$A$58 -> -350 | O31: =-$A$58 -> -350 | P31: =-$A$58 -> -350 | Q31: =-$A$58 -> -350 | R31: =-$A$58 -> -350 | S31: =-$A$58 -> -350 | T31: =-$A$58 -> -350 | ... AD31: =-$A$58 -> -350 | AE31: -400 | AF31: -400 | AG31: -400 | AH31: -420 | AI31: -440 | AJ31: -460 | AK31: -459 | AL31: -458 | AM31: -457 | AN31: -456 | AO31: -455 | AP31: -454 | AQ31: -453 | AR31: -452 | AS31: -451 | AT31: -450 | AU31: -449 | AV31: -448 | AW31: -447 | AX31: -446 | AY31: -445 | AZ31: -444 | BA31: -443 | BB31: -442 | BC31: -441 | BD31: -440 | BE31: -439 | BF31: -438 | BG31: -437 | BH31: -436 | BI31: -435 | BJ31: -434 | BK31: -433 | BL31: -432 | BM31: -431 | BN31: -430 | BO31: -429 | BP31: -428 | BQ31: -427 | BR31: -426 | BS31: -425 | BT31: -424 | BU31: -423 | BV31: -422 | BW31: -421
B32: Prezzo magazzino | M32: =-A57 -> -5000
A33: Tasse bancarelle
A34: 📜 | B34: Tassa bancarella Kanemura | D34: =-$A$59 -> -25 | E34: =-$A$59 -> -25 | F34: =-$A$59 -> -25 | G34: =-$A$59 -> -25 | H34: =-$A$59 -> -25 | I34: =-$A$59 -> -25 | J34: =-$A$59 -> -25 | K34: =-$A$59 -> -25 | ... BW34: =-$A$59 -> -25
A35: 📜 | B35: Tassa bancarella Takamura | D35: =-$A$59 -> -25 | E35: =-$A$59 -> -25 | F35: =-$A$59 -> -25 | G35: =-$A$59 -> -25 | H35: =-$A$59 -> -25 | I35: =-$A$59 -> -25 | J35: =-$A$59 -> -25 | K35: =-$A$59 -> -25 | ... BW35: =-$A$59 -> -25
A36: 📜 | B36: Tassa bancarella Umihana | G36: =-$A$59 -> -25 | H36: =-$A$59 -> -25 | I36: =-$A$59 -> -25 | J36: =-$A$59 -> -25 | K36: =-$A$59 -> -25 | L36: =-$A$59 -> -25 | M36: =-$A$59 -> -25 | N36: =-$A$59 -> -25 | ... BW36: =-$A$59 -> -25
A37: ⭐️ | B37: Storia e Arte
A38: ⭐️ | B38: Modi di fare
A39: Assicurazione | D39: =-SUMIF(D11:D32, ">=0")*$A$63 -> -33 | E39: =-SUMIF(E11:E32, ">=0")*$A$63 -> -33 | F39: =-SUMIF(F11:F32, ">=0")*$A$63 -> -33 | G39: =-SUMIF(G11:G32, ">=0")*$A$63 -> -52.8 | H39: =-SUMIF(H11:H32, ">=0")*$A$63 -> -52.8 | I39: =-SUMIF(I11:I32, ">=0")*$A$63 -> -52.8 | J39: =-SUMIF(J11:J32, ">=0")*$A$63 -> -72.6 | K39: =-SUMIF(K11:K32, ">=0")*$A$63 -> -72.6 | ... BW39: =-SUMIF(BW11:BW32, ">=0")*$A$63 -> -130.02
A42: {=SUM(COUNTIF(A11:A36, {"📜","👤"})) & "/13 Permessi"} -> 13/13 Permessi | C42: Bottino di partenza | L42: Riso Masanori | S42: Collana in oro con perle, regalata ai Nagatomo | V42: Tip per Masanori | AB42: consiglio legale relitto | AJ42: set da tè | AK42: -100
...

Sheet Zilla
F1: Zilla | H1: Aprile | I1: Maggio | J1: Giugno | K1: Luglio | L1: Agosto | M1: Settembre | N1: Ottobre | O1: Novembre | P1: Dicembre | Q1: Gennaio | R1: Febbraio | S1: Marzo | T1: Aprile | U1: Maggio | V1: Giugno | W1: Luglio | X1: Agosto | Y1: Settembre | Z1: Ottobre | AA1: Novembre | AB1: Dicembre | AC1: Gennaio | AD1: Febbraio | AE1: Marzo | AF1: Aprile | AG1: Maggio | AH1: Giugno | AI1: Luglio | AJ1: Agosto | AK1: Settembre | AL1: Ottobre | AM1: Novembre | AN1: Dicembre | AO1: Gennaio | AP1: Febbraio | AQ1: Marzo | AR1: Aprile | AS1: Maggio | AT1: Giugno | AU1: Luglio | AV1: Agosto | AW1: Settembre | AX1: Ottobre | AY1: Novembre | AZ1: Dicembre | BA1: Gennaio | BB1: Febbraio | BC1: Marzo | BD1: Aprile | BE1: Maggio | BF1: Giugno | BG1: Luglio | BH1: Agosto | BI1: Settembre | BJ1: Ottobre | BK1: Novembre | BL1: Dicembre | BM1: Gennaio | BN1: Febbraio | BO1: Marzo | BP1: Aprile | BQ1: Maggio | BR1: Giugno | BS1: Luglio | BT1: Agosto | BU1: Settembre | BV1: Ottobre | BW1: Novembre | BX1: Dicembre | BY1: Gennaio | BZ1: Febbraio | CA1: Marzo | CB1: Aprile | CC1: Maggio | CD1: Giugno | CE1: Luglio | CF1: Agosto | CG1: Settembre | CH1: Ottobre | CI1: Novembre | CJ1: Dicembre | CK1: Gennaio | CL1: Febbraio | CM1: Marzo | CN1: Aprile | CO1: Maggio | CP1: Giugno | CQ1: Luglio | CR1: Agosto | CS1: Settembre | CT1: Ottobre | CU1: Novembre | CV1: Dicembre
F2: Anno | H2: 1532 | I2: =H2+IF(I1="Gennaio",1,0) -> 1532 | J2: =I2+IF(J1="Gennaio",1,0) -> 1532 | K2: =J2+IF(K1="Gennaio",1,0) -> 1532 | L2: =K2+IF(L1="Gennaio",1,0) -> 1532 | M2: =L2+IF(M1="Gennaio",1,0) -> 1532 | N2: =M2+IF(N1="Gennaio",1,0) -> 1532 | O2: =N2+IF(O1="Gennaio",1,0) -> 1532 | P2: =O2+IF(P1="Gennaio",1,0) -> 1532 | ... CV2: =CU2+IF(CV1="Gennaio",1,0) -> 1539
F3: Mese in-game | H3: =G3+1 -> 1 | I3: =H3+1 -> 2 | J3: =I3+1 -> 3 | K3: =J3+1 -> 4 | L3: =K3+1 -> 5 | M3: =L3+1 -> 6 | N3: =M3+1 -> 7 | O3: =N3+1 -> 8 | ... CV3: =CU3+1 -> 93
F5: AV | G5: =ABS(G60) -> 75 | H5: =ABS(H22+H60) -> 1850 | K5: =ABS(K28) -> 900 | M5: =ABS(M57) -> 1000 | N5: =ABS(N34) -> 900 | Q5: =ABS(Q41+Q57) -> 320 | R5: =ABS(R57) -> 30 | V5: =ABS(V60) -> 500 | AE5: =-AE61 -> 130 | AF5: =-AF41-(6900+500)-AF57 -> 4900 | AL5: =ABS(AL57+AL58) -> 15500
F6: NAV | H6: =SUM($G5:H5)+H8 -> 5602 | I6: =SUM($G5:I5)+I8 -> 6204 | J6: =SUM($G5:J5)+J8 -> 6732.6667 | K6: =SUM($G5:K5)+K8 -> 7549.8667 | L6: =SUM($G5:L5)+L8 -> 8330.4 | M6: =SUM($G5:M5)+M8 -> 9147.6 | N6: =SUM($G5:N5)+N8 -> 10180 | O6: =SUM($G5:O5)+O8 -> 11212.4 | ... CA6: =SUM($G5:CA5)+CA8 -> 110595.98
F8: Liquidi | G8: =SUM(G12:G1048576) -> 4925 | H8: =G8+SUM(H12:H1048576) -> 3677 | I8: =H8+SUM(I12:I1048576) -> 4279 | J8: =I8+SUM(J12:J1048576) -> 4807.6667 | K8: =J8+SUM(K12:K1048576) -> 4724.8667 | L8: =K8+SUM(L12:L1048576) -> 5505.4 | M8: =L8+SUM(M12:M1048576) -> 5322.6 | N8: =M8+SUM(N12:N1048576) -> 5455 | O8: =N8+SUM(O12:O1048576) -> 6487.4 | ... CA8: =BZ8+SUM(CA12:CA1048576) -> 84490.98
F9: Profitto netto | H9: =H8-G8 -> -1248 | I9: =I8-H8 -> 602 | J9: =J8-I8 -> 528.66667 | K9: =K8-J8 -> -82.8 | L9: =L8-K8 -> 780.53333 | M9: =M8-L8 -> -182.8 | N9: =N8-M8 -> 132.4 | O9: =O8-N8 -> 1032.4 | ... CA9: =CA8-BZ8 -> 1702.0543
F12: Cibo | H12: -250 | I12: -250 | J12: -250 | K12: -250 | L12: -250 | M12: -250 | N12: -250 | O12: -250 | P12: -250 | Q12: -250 | R12: -250 | S12: -250 | T12: -250 | U12: -250 | V12: -250 | W12: -250 | X12: -250 | Y12: -250 | Z12: -250 | AA12: -250 | AB12: -250 | AC12: -250 | AD12: -250 | AE12: -250 | AF12: -250 | AG12: -250 | AH12: -250 | AI12: -250 | AJ12: -250 | AK12: -250 | AL12: -250 | AM12: -250 | AN12: -250 | AO12: -250 | AP12: -250 | AQ12: -250 | AR12: -250 | AS12: -250 | AT12: -250 | AU12: -250 | AV12: -250 | AW12: -250 | AX12: -250 | AY12: -250 | AZ12: -250 | BA12: -250 | BB12: -250 | BC12: -250 | BD12: -250 | BE12: -250 | BF12: -250 | BG12: -250 | BH12: -250 | BI12: -250 | BJ12: -250 | BK12: -250 | BL12: -250 | BM12: -250 | BN12: -250 | BO12: -250 | BP12: -250 | BQ12: -250 | BR12: -250 | BS12: -250 | BT12: -250 | BU12: -250 | BV12: -250 | BW12: -250 | BX12: -250 | BY12: -250 | BZ12: -250 | CA12: -250
F13: Affitto | H13: -90 | I13: -90 | J13: -90 | K13: -90 | L13: -90 | M13: -90 | N13: -90 | O13: -90 | P13: -90 | Q13: -90 | R13: -90 | S13: -90 | T13: -90 | U13: -90 | V13: -90 | W13: -90 | X13: -90 | Y13: -90 | Z13: -90 | AA13: -90 | AB13: -90 | AC13: -90 | AD13: -90 | AE13: -90 | AF13: -90 | AG13: -90 | AH13: -90 | AI13: -90 | AJ13: -90 | AK13: -90 | AL13: -90 | AM13: -90 | AN13: -90 | AO13: -90 | AP13: -90 | AQ13: -90 | AR13: -90 | AS13: -90 | AT13: -90 | AU13: -90 | AV13: -90 | AW13: -90 | AX13: -90 | AY13: -90 | AZ13: -90 | BA13: -90 | BB13: -90 | BC13: -90 | BD13: -90 | BE13: -90 | BF13: -90 | BG13: -90 | BH13: -90 | BI13: -90 | BJ13: -90 | BK13: -90 | BL13: -90 | BM13: -90 | BN13: -90 | BO13: -90 | BP13: -90 | BQ13: -90 | BR13: -90 | BS13: -90 | BT13: -90 | BU13: -90 | BV13: -90 | BW13: -90 | BX13: -90 | BY13: -90 | BZ13: -90 | CA13: -90
E14: =COUNTA(B15:C56) -> 11 | F14: / 11 Permessi
F16: Tratta 1 (U-H-T)
F17: Tratta 1 (T-H-U)
F18: Mercante (Zilla) | H18: =$E$65 -> 1100 | I18: =$E$65 -> 1100 | J18: =$E$65 -> 1100 | K18: =$E$65 -> 1100 | L18: =$E$65 -> 1100 | M18: =$E$65 -> 1100 | N18: =$E$65 -> 1100 | O18: =$E$65 -> 1100 | ... CA18: =$E$65 -> 1100
E19: ⭐️ | F19: Apprendista mercante | Z19: =$E$65*$E$67*$E$68 -> 528 | AA19: =$E$65*$E$67*$E$68 -> 528 | AB19: =$E$65*$E$67*$E$68 -> 528 | AC19: =$E$65*$E$67*$E$68 -> 528 | AD19: =$E$65*$E$67*$E$68 -> 528 | AE19: =$E$65*$E$67*$E$68 -> 528 | AF19: =$E$65*$E$67*$E$68 -> 528 | AG19: =$E$65*$E$67*$E$68 -> 528 | ... CA19: =$E$65*$E$67*$E$68 -> 528
F20: salario | Z20: =-$E$66 -> -300 | AA20: =-$E$66 -> -300 | AB20: =-$E$66 -> -300 | AC20: =-$E$66 -> -300 | AD20: =-$E$66 -> -300 | AE20: =-$E$66 -> -300 | AF20: =-$E$66 -> -300 | AG20: =-$E$66 -> -300 | AH20: =-$E$66 -> -300 | AI20: -400 | AJ20: -400 | AK20: -400 | AL20: -400 | AM20: -400 | AN20: -400 | AO20: -400 | AP20: -400 | AQ20: -400 | AR20: -400 | AS20: -400 | AT20: -400 | AU20: -400 | AV20: -400 | AW20: -400 | AX20: -400 | AY20: -400 | AZ20: -400 | BA20: -400 | BB20: -400 | BC20: -400 | BD20: -400 | BE20: -400 | BF20: -400 | BG20: -400 | BH20: -400 | BI20: -400 | BJ20: -400 | BK20: -400 | BL20: -400 | BM20: -400 | BN20: -400 | BO20: -400 | BP20: -400 | BQ20: -400 | BR20: -400 | BS20: -400 | BT20: -400 | BU20: -400 | BV20: -400 | BW20: -400 | BX20: -399 | BY20: -398 | BZ20: -397 | CA20: -396
B21: 📜 | F21: Tassa rotta commerciale | H21: =-$E$70 -> -100 | I21: =-$E$70 -> -100 | J21: =-$E$70 -> -100 | K21: =-$E$70 -> -100 | L21: =-$E$70 -> -100 | M21: =-$E$70 -> -100 | N21: =-$E$70 -> -100 | O21: =-$E$70 -> -100 | ... CA21: =-$E$70 -> -100
F22: Carro, cavallo, barili | H22: -900
F25: Tratta 2 (U-H-T) | K25: =$E$65*$E$67 -> 660 | L25: =$E$65*$E$67 -> 660 | M25: =$E$65*$E$67 -> 660 | N25: =$E$65*$E$67 -> 660 | O25: =$E$65*$E$67 -> 660 | P25: =$E$65*$E$67 -> 660 | Q25: =$E$65*$E$67 -> 660 | R25: =$E$65*$E$67 -> 660 | ... CA25: =$E$65*$E$67 -> 660
B26: 👤 | F26: Apprendista mercante | K26: =-$E$66 -> -300 | L26: =-$E$66 -> -300 | M26: =-$E$66 -> -300 | N26: =-$E$66 -> -300 | O26: =-$E$66 -> -300 | P26: =-$E$66 -> -300 | Q26: =-$E$66 -> -300 | R26: =-$E$66 -> -300 | ... AH26: =-$E$66 -> -300 | AI26: -400 | AJ26: -400 | AK26: -400 | AL26: -399 | AM26: -398 | AN26: -397 | AO26: -396 | AP26: -395 | AQ26: -394 | AR26: -393 | AS26: -392 | AT26: -391 | AU26: -390 | AV26: -389 | AW26: -388 | AX26: -387 | AY26: -386 | AZ26: -385 | BA26: -384 | BB26: -383 | BC26: -382 | BD26: -381 | BE26: -380 | BF26: -379 | BG26: -378 | BH26: -377 | BI26: -376 | BJ26: -375 | BK26: -374 | BL26: -373 | BM26: -372 | BN26: -371 | BO26: -370 | BP26: -369 | BQ26: -368 | BR26: -367 | BS26: -366 | BT26: -365 | BU26: -364 | BV26: -363 | BW26: -362 | BX26: -361 | BY26: -360 | BZ26: -359 | CA26: -358
B27: 📜 | F27: Tassa rotta commerciale | K27: =-$E$70 -> -100 | L27: =-$E$70 -> -100 | M27: =-$E$70 -> -100 | N27: =-$E$70 -> -100 | O27: =-$E$70 -> -100 | P27: =-$E$70 -> -100 | Q27: =-$E$70 -> -100 | R27: =-$E$70 -> -100 | ... CA27: =-$E$70 -> -100
F28: Carro, cavallo, barili | K28: -900
F31: Tratta 3 (K-H-U) | N31: =$E$65*$E$67 -> 660 | O31: =$E$65*$E$67 -> 660 | P31: =$E$65*$E$67 -> 660 | Q31: =$E$65*$E$67 -> 660 | R31: =$E$65*$E$67 -> 660 | S31: =$E$65*$E$67 -> 660 | T31: =$E$65*$E$67 -> 660 | U31: =$E$65*$E$67 -> 660 | ... CA31: =$E$65*$E$67 -> 660
B32: 👤 | F32: Apprendista mercante | N32: =-$E$66 -> -300 | O32: =-$E$66 -> -300 | P32: =-$E$66 -> -300 | Q32: =-$E$66 -> -300 | R32: =-$E$66 -> -300 | S32: =-$E$66 -> -300 | T32: =-$E$66 -> -300 | U32: =-$E$66 -> -300 | ... AH32: =-$E$66 -> -300 | AI32: -400 | AJ32: -400 | AK32: -400 | AL32: -399 | AM32: -398 | AN32: -397 | AO32: -396 | AP32: -395 | AQ32: -394 | AR32: -393 | AS32: -392 | AT32: -391 | AU32: -390 | AV32: -389 | AW32: -388 | AX32: -387 | AY32: -386 | AZ32: -385 | BA32: -384 | BB32: -383 | BC32: -382 | BD32: -381 | BE32: -380 | BF32: -379 | BG32: -378 | BH32: -377 | BI32: -376 | BJ32: -375 | BK32: -374 | BL32: -373 | BM32: -372 | BN32: -371 | BO32: -370 | BP32: -369 | BQ32: -368 | BR32: -367 | BS32: -366 | BT32: -365 | BU32: -364 | BV32: -363 | BW32: -362 | BX32: -361 | BY32: -360 | BZ32: -359 | CA32: -358
B33: 📜 | F33: Tassa rotta commerciale | N33: =-$E$70 -> -100 | O33: =-$E$70 -> -100 | P33: =-$E$70 -> -100 | Q33: =-$E$70 -> -100 | R33: =-$E$70 -> -100 | S33: =-$E$70 -> -100 | T33: =-$E$70 -> -100 | U33: =-$E$70 -> -100 | ... CA33: =-$E$70 -> -100
F34: Carro, cavallo, barili | N34: -900
F37: Magazzini (rotte 1, 2, 3)
F38: Boost vendite | Q38: =(Q18+Q25+Q31)*$E$71 -> 532.4 | R38: =(R18+R25+R31)*$E$71 -> 532.4 | S38: =(S18+S25+S31)*$E$71 -> 532.4 | T38: =(T18+T25+T31)*$E$71 -> 532.4 | U38: =(U18+U25+U31)*$E$71 -> 532.4 | V38: =(V18+V25+V31)*$E$71 -> 532.4 | W38: =(W18+W25+W31)*$E$71 -> 532.4 | X38: =(X18+X25+X31)*$E$71 -> 532.4 | Y38: =(Y18+Y25+Y31)*$E$71 -> 532.4 | Z38: =(Z18+Z25+Z31+Z19)*$E$71 -> 648.56 | AA38: =(AA18+AA25+AA31+AA19)*$E$71 -> 648.56 | AB38: =(AB18+AB25+AB31+AB19)*$E$71 -> 648.56 | AC38: =(AC18+AC25+AC31+AC19)*$E$71 -> 648.56 | AD38: =(AD18+AD25+AD31+AD19)*$E$71 -> 648.56 | AE38: =(AE18+AE25+AE31+AE19)*$E$71 -> 648.56 | AF38: =(AF18+AF25+AF31+AF19)*$E$72 -> 1474 | AG38: =(AG18+AG25+AG31+AG19)*$E$72 -> 1474 | AH38: =(AH18+AH25+AH31+AH19)*$E$72 -> 1474 | AI38: =(AI18+AI25+AI31+AI19)*$E$72 -> 1474 | AJ38: =(AJ18+AJ25+AJ31+AJ19)*$E$72 -> 1474 | AK38: =(AK18+AK25+AK31+AK19)*$E$72 -> 1474 | AL38: =(AL18+AL25+AL31+AL19)*$E$72 -> 1474 | AM38: =(AM18+AM25+AM31+AM19)*$E$72 -> 1474 | ... CA38: =(CA18+CA25+CA31+CA19)*$E$72 -> 1474
B39: 👤 | C39: 👤 | F39: Mantenimento | Q39: =-$E$74 -> -350 | R39: =-$E$74 -> -350 | S39: =-$E$74 -> -350 | T39: =-$E$74 -> -350 | U39: =-$E$74 -> -350 | V39: =-$E$74 -> -350 | W39: =-$E$74 -> -350 | X39: =-$E$74 -> -350 | ... AE39: =-$E$74 -> -350 | AF39: =-$E$74*2 -> -700 | AG39: =-$E$74*2 -> -700 | AH39: =-$E$74*2 -> -700 | AI39: =-$E$74*2 -> -700 | AJ39: =-$E$74*2 -> -700 | AK39: =-$E$74*2 -> -700 | AL39: =-$E$74*2 -> -700 | AM39: =-$E$74*2 -> -700 | ... CA39: =-$E$74*2 -> -700
F40: magazzino miccolo Umihana | P40: magazzino piccolo | Q40: era 69 gold
B41: 📜 | F41: magazzino grande Umihana | AE41: magazzino grande | AF41: -12000
F44: Bancarelle
B45: 📜 | F45: Tassa bancarella Kanemura | H45: =-$E$69 -> -25 | I45: =-$E$69 -> -25 | J45: =-$E$69 -> -25 | K45: =-$E$69 -> -25 | L45: =-$E$69 -> -25 | M45: =-$E$69 -> -25 | N45: =-$E$69 -> -25 | O45: =-$E$69 -> -25 | ... CA45: =-$E$69 -> -25
B46: 📜 | F46: Tassa bancarella Takamura | K46: =-$E$69 -> -25 | L46: =-$E$69 -> -25 | M46: =-$E$69 -> -25 | N46: =-$E$69 -> -25 | O46: =-$E$69 -> -25 | P46: =-$E$69 -> -25 | Q46: =-$E$69 -> -25 | R46: =-$E$69 -> -25 | ... CA46: =-$E$69 -> -25
B47: 📜 | F47: Tassa bancarella Umihana | N47: =-$E$69 -> -25 | O47: =-$E$69 -> -25 | P47: =-$E$69 -> -25 | Q47: =-$E$69 -> -25 | R47: =-$E$69 -> -25 | S47: =-$E$69 -> -25 | T47: =-$E$69 -> -25 | U47: =-$E$69 -> -25 | ... CA47: =-$E$69 -> -25
F48: 🔒
E50: ⭐️ | F50: Pesca con l'arco | AC50: =1/7*500/2 -> 35.714286 | AD50: =1/7*500/2 -> 35.714286 | AE50: =1/7*500/2 -> 35.714286 | AF50: =1/7*500/2 -> 35.714286 | AG50: =1/7*500/2 -> 35.714286 | AH50: =1/7*500/2 -> 35.714286 | AI50: =1/7*500/2 -> 35.714286 | AJ50: =1/7*500/2 -> 35.714286 | ... CA50: =1/7*500/2 -> 35.714286
F51: Beneficenza tempio Takamura | AC51: -103 | AD51: -102 | AE51: -101 | AF51: -100 | AG51: -100 | AH51: -100 | AI51: -100 | AJ51: -100 | AK51: -100 | AL51: -100 | AM51: -100 | AN51: -100 | AO51: -100 | AP51: -100 | AQ51: -100 | AR51: -100 | AS51: -100 | AT51: -100 | AU51: -100 | AV51: -100 | AW51: -100 | AX51: -100 | AY51: -100 | AZ51: -100 | BA51: -100 | BB51: -100 | BC51: -100 | BD51: -100 | BE51: -100 | BF51: -100 | BG51: -100 | BH51: -100 | BI51: -100 | BJ51: -100 | BK51: -100 | BL51: -100 | BM51: -100 | BN51: -100 | BO51: -100 | BP51: -100 | BQ51: -100 | BR51: -100 | BS51: -100 | BT51: -100 | BU51: -100 | BV51: -100 | BW51: -100 | BX51: -99 | BY51: -98 | BZ51: -97 | CA51: -96
F54: Assicurazione | H54: =-SUMIF(H17:H48, ">=0")*$E$78 -> -33 | I54: =-SUMIF(I17:I48, ">=0")*$E$78 -> -33 | J54: =-SUMIF(J17:J48, ">=0")*$E$78 -> -33 | K54: =-SUMIF(K17:K48, ">=0")*$E$78 -> -52.8 | L54: =-SUMIF(L17:L48, ">=0")*$E$78 -> -52.8 | M54: =-SUMIF(M17:M48, ">=0")*$E$78 -> -52.8 | N54: =-SUMIF(N17:N48, ">=0")*$E$78 -> -72.6 | O54: =-SUMIF(O17:O48, ">=0")*$E$78 -> -72.6 | ... CA54: =-SUMIF(CA17:CA48, ">=0")*$E$78 -> -132.66
G56: Bottino di partenza | M56: Katane Mayakashi 205, 208 | Q56: Monete Cinesi d'oro | R56: tè con marchio e sigillo imperiale cinese | AE56: Kimono per Saori | AF56: -700
G57: 5000 | M57: -1000 | Q57: -320 | R57: -30 | AE57: Kimono per se stesso (3+1) | AF57: -300 | AK57: katana | AL57: -2000
...

Sheet Vito
D1: Vito | F1: Aprile | G1: Maggio | H1: Giugno | I1: Luglio | J1: Agosto | K1: Settembre | L1: Ottobre | M1: Novembre | N1: Dicembre | O1: Gennaio | P1: Febbraio | Q1: Marzo | R1: Aprile | S1: Maggio | T1: Giugno | U1: Luglio | V1: Agosto | W1: Settembre | X1: Ottobre | Y1: Novembre | Z1: Dicembre | AA1: Gennaio | AB1: Febbraio | AC1: Marzo | AD1: Aprile | AE1: Maggio | AF1: Giugno | AG1: Luglio | AH1: Agosto | AI1: Settembre | AJ1: Ottobre | AK1: Novembre | AL1: Dicembre | AM1: Gennaio | AN1: Febbraio | AO1: Marzo | AP1: Aprile | AQ1: Maggio | AR1: Giugno | AS1: Luglio | AT1: Agosto | AU1: Settembre | AV1: Ottobre | AW1: Novembre | AX1: Dicembre | AY1: Gennaio | AZ1: Febbraio | BA1: Marzo | BB1: Aprile | BC1: Maggio | BD1: Giugno | BE1: Luglio | BF1: Agosto | BG1: Settembre | BH1: Ottobre | BI1: Novembre | BJ1: Dicembre | BK1: Gennaio | BL1: Febbraio | BM1: Marzo | BN1: Aprile | BO1: Maggio | BP1: Giugno | BQ1: Luglio | BR1: Agosto | BS1: Settembre | BT1: Ottobre | BU1: Novembre | BV1: Dicembre | BW1: Gennaio | BX1: Febbraio | BY1: Marzo | BZ1: Aprile | CA1: Maggio | CB1: Giugno | CC1: Luglio | CD1: Agosto | CE1: Settembre | CF1: Ottobre | CG1: Novembre | CH1: Dicembre | CI1: Gennaio | CJ1: Febbraio | CK1: Marzo | CL1: Aprile | CM1: Maggio | CN1: Giugno | CO1: Luglio | CP1: Agosto | CQ1: Settembre | CR1: Ottobre | CS1: Novembre | CT1: Dicembre
D2: Anno | F2: 1532 | G2: =F2+IF(G1="Gennaio",1,0) -> 1532 | H2: =G2+IF(H1="Gennaio",1,0) -> 1532 | I2: =H2+IF(I1="Gennaio",1,0) -> 1532 | J2: =I2+IF(J1="Gennaio",1,0) -> 1532 | K2: =J2+IF(K1="Gennaio",1,0) -> 1532 | L2: =K2+IF(L1="Gennaio",1,0) -> 1532 | M2: =L2+IF(M1="Gennaio",1,0) -> 1532 | N2: =M2+IF(N1="Gennaio",1,0) -> 1532 | ... CT2: =CS2+IF(CT1="Gennaio",1,0) -> 1539
D3: Mese in-game | F3: =E3+1 -> 1 | G3: =F3+1 -> 2 | H3: =G3+1 -> 3 | I3: =H3+1 -> 4 | J3: =I3+1 -> 5 | K3: =J3+1 -> 6 | L3: =K3+1 -> 7 | M3: =L3+1 -> 8 | ... CT3: =CS3+1 -> 93
D5: AV | O5: =ABS(O34) -> 350 | U5: =ABS(U33+U36) -> 800
D6: NAV | F6: =SUM($E5:F5)+F8 -> 5223 | G6: =SUM($E5:G5)+G8 -> 5479 | H6: =SUM($E5:H5)+H8 -> 5774 | I6: =SUM($E5:I5)+I8 -> 6024 | J6: =SUM($E5:J5)+J8 -> 6304 | K6: =SUM($E5:K5)+K8 -> 6584 | L6: =SUM($E5:L5)+L8 -> 6864 | M6: =SUM($E5:M5)+M8 -> 7144 | ... BY6: =SUM($E5:BY5)+BY8 -> 51504
D8: Liquidi | E8: =SUM(E11:E1048576) -> 5000 | F8: =E8+SUM(F11:F1048576) -> 5223 | G8: =F8+SUM(G11:G1048576) -> 5479 | H8: =G8+SUM(H11:H1048576) -> 5774 | I8: =H8+SUM(I11:I1048576) -> 6024 | J8: =I8+SUM(J11:J1048576) -> 6304 | K8: =J8+SUM(K11:K1048576) -> 6584 | L8: =K8+SUM(L11:L1048576) -> 6864 | M8: =L8+SUM(M11:M1048576) -> 7144 | ... BY8: =BX8+SUM(BY11:BY1048576) -> 50354
D9: Profitto netto | F9: =F8-E8 -> 223 | G9: =G8-F8 -> 256 | H9: =H8-G8 -> 295 | I9: =I8-H8 -> 250 | J9: =J8-I8 -> 280 | K9: =K8-J8 -> 280 | L9: =L8-K8 -> 280 | M9: =M8-L8 -> 280 | ... BY9: =BY8-BX8 -> 2470
D12: Cibo | F12: 0 | G12: 0 | H12: 0 | I12: 0 | J12: 0 | K12: 0 | L12: 0 | M12: 0 | N12: 0 | O12: 0 | P12: 0 | Q12: 0 | R12: 0 | S12: 0 | T12: 0 | U12: 0 | V12: 0 | W12: 0 | X12: 0 | Y12: 0 | Z12: 0 | AA12: 0 | AB12: 0 | AC12: 0 | AD12: 0 | AE12: 0 | AF12: 0 | AG12: 0 | AH12: 0 | AI12: 0 | AJ12: 0 | AK12: 0 | AL12: 0 | AM12: 0 | AN12: 0 | AO12: 0 | AP12: 0 | AQ12: 0 | AR12: 0 | AS12: 0 | AT12: 0 | AU12: 0 | AV12: 0 | AW12: 0 | AX12: 0 | AY12: 0 | AZ12: 0 | BA12: 0 | BB12: 0 | BC12: 0 | BD12: 0 | BE12: 0 | BF12: 0 | BG12: 0 | BH12: 0 | BI12: 0 | BJ12: 0 | BK12: 0 | BL12: 0 | BM12: 0 | BN12: 0 | BO12: 0 | BP12: 0 | BQ12: 0 | BR12: 0 | BS12: 0 | BT12: 0 | BU12: 0 | BV12: 0 | BW12: 0 | BX12: 0 | BY12: 0
D13: Affitto | F13: 0 | G13: 0 | H13: 0 | I13: 0 | J13: 0 | K13: 0 | L13: 0 | M13: 0 | N13: 0 | O13: 0 | P13: 0 | Q13: 0 | R13: 0 | S13: 0 | T13: 0 | U13: 0 | V13: 0 | W13: 0 | X13: 0 | Y13: 0 | Z13: 0 | AA13: 0 | AB13: 0 | AC13: 0 | AD13: 0 | AE13: 0 | AF13: 0 | AG13: 0 | AH13: 0 | AI13: 0 | AJ13: 0 | AK13: 0 | AL13: 0 | AM13: 0 | AN13: 0 | AO13: 0 | AP13: 0 | AQ13: 0 | AR13: 0 | AS13: 0 | AT13: 0 | AU13: 0 | AV13: 0 | AW13: 0 | AX13: 0 | AY13: 0 | AZ13: 0 | BA13: 0 | BB13: 0 | BC13: 0 | BD13: 0 | BE13: 0 | BF13: 0 | BG13: 0 | BH13: 0 | BI13: 0 | BJ13: 0 | BK13: 0 | BL13: 0 | BM13: 0 | BN13: 0 | BO13: 0 | BP13: 0 | BQ13: 0 | BR13: 0 | BS13: 0 | BT13: 0 | BU13: 0 | BV13: 0 | BW13: 0 | BX13: 0 | BY13: 0
C14: =COUNTA(A15:B41) -> 3 | D14: Permessi
D16: Impiego
D17: Assistente
C18: ⭐️ | D18: Salario | I18: =$C$41 -> 280 | J18: =$C$41 -> 280 | K18: =$C$41 -> 280 | L18: =$C$41 -> 280 | M18: =$C$41 -> 280 | N18: =$C$41 -> 280 | O18: =$C$41 -> 280 | P18: =$C$41 -> 280 | ... BY18: =$C$41 -> 280
D21: Servizio Postale a Cavallo | AJ21: aiuto zilla
D22: vendite | AD22: =AC22+40 -> 40 | AE22: =AD22+40 -> 80 | AF22: =AE22+40 -> 120 | AG22: =AF22+40 -> 160 | AH22: =AG22+40 -> 200 | AI22: =AH22+40 -> 240 | AJ22: =AI22+70 -> 310 | AK22: =AJ22+70 -> 380 | AL22: =AK22+70 -> 450 | AM22: =AL22+70 -> 520 | AN22: =AM22+70 -> 590 | AO22: =AN22+70 -> 660 | AP22: =AO22+70 -> 730 | AQ22: =AP22+70 -> 800 | ... BY22: =BX22+70 -> 3180
B23: 📜 | D23: dipendente Kanemura | AD23: -330 | AE23: -330 | AF23: -330 | AG23: -330 | AH23: -330 | AI23: -330 | AJ23: -330 | AK23: -330 | AL23: -330 | AM23: -330 | AN23: -330 | AO23: -330 | AP23: -330 | AQ23: -330 | AR23: -330 | AS23: -330 | AT23: -330 | AU23: -330 | AV23: -330 | AW23: -330 | AX23: -330 | AY23: -330 | AZ23: -330 | BA23: -330 | BB23: -330 | BC23: -330 | BD23: -330 | BE23: -330 | BF23: -330 | BG23: -330 | BH23: -330 | BI23: -330 | BJ23: -330 | BK23: -330 | BL23: -330 | BM23: -330 | BN23: -330 | BO23: -330 | BP23: -330 | BQ23: -330 | BR23: -330 | BS23: -330 | BT23: -330 | BU23: -330 | BV23: -330 | BW23: -330 | BX23: -330 | BY23: -330
B24: 📜 | D24: dipendente Takamura | AD24: -330 | AE24: -330 | AF24: -330 | AG24: -330 | AH24: -330 | AI24: -330 | AJ24: -330 | AK24: -330 | AL24: -330 | AM24: -330 | AN24: -330 | AO24: -330 | AP24: -330 | AQ24: -330 | AR24: -330 | AS24: -330 | AT24: -330 | AU24: -330 | AV24: -330 | AW24: -330 | AX24: -330 | AY24: -330 | AZ24: -330 | BA24: -330 | BB24: -330 | BC24: -330 | BD24: -330 | BE24: -330 | BF24: -330 | BG24: -330 | BH24: -330 | BI24: -330 | BJ24: -330 | BK24: -330 | BL24: -330 | BM24: -330 | BN24: -330 | BO24: -330 | BP24: -330 | BQ24: -330 | BR24: -330 | BS24: -330 | BT24: -330 | BU24: -330 | BV24: -330 | BW24: -330 | BX24: -330 | BY24: -330
B25: 📜 | D25: dipendente Umihana | AD25: -330 | AE25: -330 | AF25: -330 | AG25: -330 | AH25: -330 | AI25: -330 | AJ25: -330 | AK25: -330 | AL25: -330 | AM25: -330 | AN25: -330 | AO25: -330 | AP25: -330 | AQ25: -330 | AR25: -330 | AS25: -330 | AT25: -330 | AU25: -330 | AV25: -330 | AW25: -330 | AX25: -330 | AY25: -330 | AZ25: -330 | BA25: -330 | BB25: -330 | BC25: -330 | BD25: -330 | BE25: -330 | BF25: -330 | BG25: -330 | BH25: -330 | BI25: -330 | BJ25: -330 | BK25: -330 | BL25: -330 | BM25: -330 | BN25: -330 | BO25: -330 | BP25: -330 | BQ25: -330 | BR25: -330 | BS25: -330 | BT25: -330 | BU25: -330 | BV25: -330 | BW25: -330 | BX25: -330 | BY25: -330
D27: Impiego
D28: Cameriera (terminato)
D29: Salario | F29: 223 | G29: 256 | H29: 295
E32: Bottino di partenza | O32: anello della nobildonna della missione | U32: vestito | AF32: tip dalle amiche | AG32: -50 | AI32: info | AJ32: -30 | AL32: info | AM32: -70
E33: 5000 | O33: -350 | U33: -600 | AI33: info | AJ33: -50
O34: 350 | AF34: Masanori | AG34: -120
I35: bribe info | Q35: bribe info | U35: orecchini e fermaglio | AL35: prestito | AM35: 5000 | AX35: ritorno prestito | AY35: =-5000*1.03 -> -5150
I36: =-10*3 -> -30 | Q36: -50 | U36: -200 | AM36: =-5000 -> -5000 | AY36: 5000
C41: 280 | D41: salario

Sheet Kleit
D1: Kleit | F1: Aprile | G1: Maggio | H1: Giugno | I1: Luglio | J1: Agosto | K1: Settembre | L1: Ottobre | M1: Novembre | N1: Dicembre | O1: Gennaio | P1: Febbraio | Q1: Marzo | R1: Aprile | S1: Maggio | T1: Giugno | U1: Luglio | V1: Agosto | W1: Settembre | X1: Ottobre | Y1: Novembre | Z1: Dicembre | AA1: Gennaio | AB1: Febbraio | AC1: Marzo | AD1: Aprile | AE1: Maggio | AF1: Giugno | AG1: Luglio | AH1: Agosto | AI1: Settembre | AJ1: Ottobre | AK1: Novembre | AL1: Dicembre | AM1: Gennaio | AN1: Febbraio | AO1: Marzo | AP1: Aprile | AQ1: Maggio | AR1: Giugno | AS1: Luglio | AT1: Agosto | AU1: Settembre | AV1: Ottobre | AW1: Novembre | AX1: Dicembre | AY1: Gennaio | AZ1: Febbraio | BA1: Marzo | BB1: Aprile | BC1: Maggio | BD1: Giugno | BE1: Luglio | BF1: Agosto | BG1: Settembre | BH1: Ottobre | BI1: Novembre | BJ1: Dicembre | BK1: Gennaio | BL1: Febbraio | BM1: Marzo | BN1: Aprile | BO1: Maggio | BP1: Giugno | BQ1: Luglio | BR1: Agosto | BS1: Settembre | BT1: Ottobre | BU1: Novembre | BV1: Dicembre | BW1: Gennaio | BX1: Febbraio | BY1: Marzo | BZ1: Aprile | CA1: Maggio | CB1: Giugno | CC1: Luglio | CD1: Agosto | CE1: Settembre | CF1: Ottobre | CG1: Novembre | CH1: Dicembre | CI1: Gennaio | CJ1: Febbraio | CK1: Marzo | CL1: Aprile | CM1: Maggio | CN1: Giugno | CO1: Luglio | CP1: Agosto | CQ1: Settembre | CR1: Ottobre | CS1: Novembre | CT1: Dicembre
D2: Anno | F2: 1532 | G2: =F2+IF(G1="Gennaio",1,0) -> 1532 | H2: =G2+IF(H1="Gennaio",1,0) -> 1532 | I2: =H2+IF(I1="Gennaio",1,0) -> 1532 | J2: =I2+IF(J1="Gennaio",1,0) -> 1532 | K2: =J2+IF(K1="Gennaio",1,0) -> 1532 | L2: =K2+IF(L1="Gennaio",1,0) -> 1532 | M2: =L2+IF(M1="Gennaio",1,0) -> 1532 | N2: =M2+IF(N1="Gennaio",1,0) -> 1532 | ... CT2: =CS2+IF(CT1="Gennaio",1,0) -> 1539
D3: Mese in-game | F3: =E3+1 -> 1 | G3: =F3+1 -> 2 | H3: =G3+1 -> 3 | I3: =H3+1 -> 4 | J3: =I3+1 -> 5 | K3: =J3+1 -> 6 | L3: =K3+1 -> 7 | M3: =L3+1 -> 8 | ... CT3: =CS3+1 -> 93
AO4: =SUMIF(AO19:AO54, ">=0") -> 4218
D5: AV | E5: =ABS(E25) -> 400 | L5: =ABS(L36+L77)-L81 -> 3650 | X5: =ABS(X81) -> 5300 | AA5: =ABS(AA48+AA54) -> 8000 | AJ5: =ABS(AG74) -> 10000
D6: NAV | F6: =SUM($E5:F5)+F10 -> 5083.4 | G6: =SUM($E5:G5)+G10 -> 5166.8 | H6: =SUM($E5:H5)+H10 -> 5250.2 | I6: =SUM($E5:I5)+I10 -> 5475.5 | J6: =SUM($E5:J5)+J10 -> 5700.8 | K6: =SUM($E5:K5)+K10 -> 6111.1 | L6: =SUM($E5:L5)+L10 -> 6566.6 | M6: =SUM($E5:M5)+M10 -> 7022.1 | ... BY6: =SUM($E5:BY5)+BY10 -> 25454.46
D8: bisognosi | AG8: 5 | AH8: 5 | AI8: 5 | AJ8: 5 | AK8: 5 | AL8: 5 | AM8: 5 | AN8: 5 | AO8: 5 | AP8: 5 | AQ8: 5 | AR8: 5 | AS8: 5 | AT8: 5 | AU8: 5 | AV8: 5 | AW8: 5 | AX8: 5 | AY8: 5 | AZ8: 5 | BA8: 5 | BB8: 5 | BC8: 5 | BD8: 5 | BE8: 5 | BF8: 5 | BG8: 5 | BH8: 5 | BI8: 5 | BJ8: 5 | BK8: 5 | BL8: 5 | BM8: 5 | BN8: 5 | BO8: 5 | BP8: 5 | BQ8: 5 | BR8: 5 | BS8: 5 | BT8: 5 | BU8: 5 | BV8: 5 | BW8: 5 | BX8: 5 | BY8: 5
D10: Liquidi | E10: =SUM(E14:E1048576) -> 4600 | F10: =E10+SUM(F14:F1048576) -> 4683.4 | G10: =F10+SUM(G14:G1048576) -> 4766.8 | H10: =G10+SUM(H14:H1048576) -> 4850.2 | I10: =H10+SUM(I14:I1048576) -> 5075.5 | J10: =I10+SUM(J14:J1048576) -> 5300.8 | K10: =J10+SUM(K14:K1048576) -> 5711.1 | L10: =K10+SUM(L14:L1048576) -> 2516.6 | M10: =L10+SUM(M14:M1048576) -> 2972.1 | ... BY10: =BX10+SUM(BY14:BY1048576) -> -1895.54
D11: Profitto netto | F11: =F10-E10 -> 83.4 | G11: =G10-F10 -> 83.4 | H11: =H10-G10 -> 83.4 | I11: =I10-H10 -> 225.3 | J11: =J10-I10 -> 225.3 | K11: =K10-J10 -> 410.3 | L11: =L10-K10 -> -3194.5 | M11: =M10-L10 -> 455.5 | ... BY11: =BY10-BX10 -> -153.54
