Workbook

Sheet Nic
B1: Nic | D1: Aprile | E1: Maggio | F1: Giugno | G1: Luglio | H1: Agosto | I1: Settembre | J1: Ottobre | K1: Novembre | L1: Dicembre | M1: Gennaio | N1: Febbraio | O1: Marzo | P1: Aprile | Q1: Maggio | R1: Giugno | S1: Luglio | T1: Agosto | U1: Settembre | V1: Ottobre | W1: Novembre | X1: Dicembre | Y1: Gennaio | Z1: Febbraio | AA1: Marzo | AB1: Aprile | AC1: Maggio | AD1: Giugno | AE1: Luglio | AF1: Agosto | AG1: Settembre | AH1: Ottobre | AI1: Novembre | AJ1: Dicembre | AK1: Gennaio | AL1: Febbraio | AM1: Marzo | AN1: Aprile | AO1: Maggio | AP1: Giugno | AQ1: Luglio | AR1: Agosto | AS1: Settembre | AT1: Ottobre | AU1: Novembre | AV1: Dicembre | AW1: Gennaio | AX1: Febbraio | AY1: Marzo | AZ1: Aprile | BA1: Maggio | BB1: Giugno | BC1: Luglio | BD1: Agosto | BE1: Settembre | BF1: Ottobre | BG1: Novembre | BH1: Dicembre | BI1: Gennaio | BJ1: Febbraio | BK1: Marzo | BL1: Aprile | BM1: Maggio | BN1: Giugno | BO1: Luglio | BP1: Agosto | BQ1: Settembre | BR1: Ottobre | BS1: Novembre | BT1: Dicembre | BU1: Gennaio | BV1: Febbraio | BW1: Marzo | BX1: Aprile | BY1: Maggio | BZ1: Giugno | CA1: Luglio | CB1: Agosto | CC1: Settembre | CD1: Ottobre | CE1: Novembre | CF1: Dicembre | CG1: Gennaio | CH1: Febbraio | CI1: Marzo | CJ1: Aprile | CK1: Maggio | CL1: Giugno | CM1: Luglio | CN1: Agosto | CO1: Settembre | CP1: Ottobre | CQ1: Novembre | CR1: Dicembre
B2: Anno | D2: 1532 | E2: =D2+IF(E1="Gennaio",1,0) -> 1532 | F2: =E2+IF(F1="Gennaio",1,0) -> 1532 | G2: =F2+IF(G1="Gennaio",1,0) -> 1532 | H2: =G2+IF(H1="Gennaio",1,0) -> 1532 | I2: =H2+IF(I1="Gennaio",1,0) -> 1532 | J2: =I2+IF(J1="Gennaio",1,0) -> 1532 | K2: =J2+IF(K1="Gennaio",1,0) -> 1532 | L2: =K2+IF(L1="Gennaio",1,0) -> 1532 | ... CR2: =CQ2+IF(CR1="Gennaio",1,0) -> 1539
B3: Mese in-game | D3: =C3+1 -> 1 | E3: =D3+1 -> 2 | F3: =E3+1 -> 3 | G3: =F3+1 -> 4 | H3: =G3+1 -> 5 | I3: =H3+1 -> 6 | J3: =I3+1 -> 7 | K3: =J3+1 -> 8 | ... CR3: =CQ3+1 -> 93
E4: attrezzi sake | P4: drip cerimonia | V4: katane | Y4: casetta per associazione pescatori | AH4: barca grande | AK4: molo Takamura
A5: =MAX(D8:CC8) -> 1850 | B5: AV | E5: =ABS(E30) -> 150 | P5: =ABS(P45) -> 700 | V5: =ABS(V46) -> 2100 | Y5: =ABS(SUM(Y44:Y47)) -> 6850 | AH5: 6000 | AK5: =ABS(AK37) -> 2500 | AP5: 21 | BX5: =-(BX47+BX50+BX53) -> 46000
A6: =MIN(D8:CC8) -> -44150 | B6: NAV | D6: =SUM($C5:D5)+D7 -> 5180 | E6: =SUM($C5:E5)+E7 -> 5450 | F6: =SUM($C5:F5)+F7 -> 5720 | G6: =SUM($C5:G5)+G7 -> 5990 | H6: =SUM($C5:H5)+H7 -> 6260 | I6: =SUM($C5:I5)+I7 -> 6530 | J6: =SUM($C5:J5)+J7 -> 6800 | K6: =SUM($C5:K5)+K7 -> 7070 | ... AI6: =SUM($C5:AI5)+AI7 -> 18260 | AJ6: =SUM($C5:AI5)+AJ7 -> 18440 | AK6: =SUM($C5:AJ5)+AK7 -> 18060 | AL6: =SUM($C5:AK5)+AL7 -> 21680 | AM6: =SUM($C5:AL5)+AM7 -> 22800 | AN6: =SUM($C5:AM5)+AN7 -> 23920 | AO6: =SUM($C5:AN5)+AO7 -> 24950 | AP6: =SUM($C5:AO5)+AP7 -> 25959 | AQ6: =SUM($C5:AP5)+AQ7 -> 27030 | ... BV6: =SUM($C5:BU5)+BV7 -> 59580 | BW6: =SUM($C5:BW5)+BW7 -> 60630 | BX6: =SUM($C5:BX5)+BX7 -> 62480 | BY6: =SUM($C5:BY5)+BY7 -> 63230 | BZ6: =SUM($C5:BZ5)+BZ7 -> 60080 | CA6: =SUM($C5:CA5)+CA7 -> 61930 | CB6: =SUM($C5:CB5)+CB7 -> 63780 | CC6: =SUM($C5:CC5)+CC7 -> 64821
B7: Liquidi | C7: =SUM(C21:C1048576) -> 5000 | D7: =C7+SUM(D21:D57) -> 5180 | E7: =D7+SUM(E21:E57) -> 5300 | F7: =E7+SUM(F21:F57) -> 5570 | G7: =F7+SUM(G21:G57) -> 5840 | H7: =G7+SUM(H21:H57) -> 6110 | I7: =H7+SUM(I21:I57) -> 6380 | J7: =I7+SUM(J21:J57) -> 6650 | K7: =J7+SUM(K21:K57) -> 6920 | ... CC7: =CB7+SUM(CC21:CC57) -> 500
B8: Profitto netto | D8: =D7-C7 -> 180 | E8: =E7-D7 -> 120 | F8: =F7-E7 -> 270 | G8: =G7-F7 -> 270 | H8: =H7-G7 -> 270 | I8: =I7-H7 -> 270 | J8: =J7-I7 -> 270 | K8: =K7-J7 -> 270 | ... CC8: =CC7-CB7 -> 1041
A9: Terreni | B9: terreno edificabile a ovest [Kawa] | Y9: 50 | Z9: 50 | AA9: 50 | AB9: 50 | AC9: 50 | AD9: 50 | AE9: 50 | AF9: 50 | AG9: 50 | AH9: 50 | AI9: 50 | AJ9: 50 | AK9: 50 | AL9: 50 | AM9: 50 | AN9: 50 | AO9: 50 | AP9: 50 | AQ9: 50 | AR9: 50 | AS9: 50 | AT9: 50 | AU9: 50 | AV9: 50 | AW9: 50 | AX9: 50 | AY9: 50 | AZ9: 50 | BA9: 50 | BB9: 50 | BC9: 50 | BD9: 50 | BE9: 50 | BF9: 50 | BG9: 50 | BH9: 50 | BI9: 50 | BJ9: 50 | BK9: 50 | BL9: 50 | BM9: 50 | BN9: 50 | BO9: 50 | BP9: 50 | BQ9: 50 | BR9: 50 | BS9: 50 | BT9: 50 | BU9: 50 | BV9: 50 | BW9: 50 | BX9: 51 | BY9: 52 | BZ9: 53 | CA9: 54 | CB9: 55 | CC9: 56
A10: Altre tasse | B10: Tassa terreno edificabile | Y10: =-Y9*$A$60 -> -25 | Z10: =-Z9*$A$60 -> -25 | AA10: =-AA9*$A$60 -> -25 | AB10: =-AB9*$A$60 -> -25 | AC10: =-AC9*$A$60 -> -25 | AD10: =-AD9*$A$60 -> -25 | AE10: =-AE9*$A$60 -> -25 | AF10: =-AF9*$A$60 -> -25 | ... CC10: =-CC9*$A$60 -> -28
A11: Barche (unità) | B11: barca grande | AH11: 1 | AI11: 1 | AJ11: 1 | AK11: 1 | AL11: 1 | AM11: 1 | AN11: 1 | AO11: 1 | AP11: 1 | AQ11: 1 | AR11: 1 | AS11: 1 | AT11: 1 | AU11: 1 | AV11: 1 | AW11: 1 | AX11: 1 | AY11: 1 | AZ11: 1 | BA11: 1 | BB11: 1 | BC11: 1 | BD11: 1 | BE11: 1 | BF11: 1 | BG11: 1 | BH11: 1 | BI11: 1 | BJ11: 1 | BK11: 1 | BL11: 1 | BM11: 1 | BN11: 1 | BO11: 1 | BP11: 1 | BQ11: 1 | BR11: 1 | BS11: 1 | BT11: 1 | BU11: 1 | BV11: 1 | BW11: 1 | BX11: 1 | BY11: 1 | BZ11: 1 | CA11: 1 | CB11: 1 | CC11: 1
B12: barca media
B13: barca piccola | Y13: 4 | Z13: 4 | AA13: 4 | AB13: 4 | AC13: 4 | AD13: 4 | AE13: 4 | AF13: 4 | AG13: 4 | AH13: 4 | AI13: 4 | AJ13: 4 | AK13: 4 | AL13: 4 | AM13: 4 | AN13: 4 | AO13: 4 | AP13: 4 | AQ13: 4 | AR13: 4 | AS13: 4 | AT13: 4 | AU13: 4 | AV13: 4 | AW13: 4 | AX13: 4 | AY13: 4 | AZ13: 4 | BA13: 4 | BB13: 4 | BC13: 4 | BD13: 4 | BE13: 4 | BF13: 4 | BG13: 4 | BH13: 4 | BI13: 4 | BJ13: 4 | BK13: 4 | BL13: 4 | BM13: 4 | BN13: 4 | BO13: 4 | BP13: 4 | BQ13: 4 | BR13: 4 | BS13: 4 | BT13: 4 | BU13: 4 | BV13: 4 | BW13: 4 | BX13: 4 | BY13: 4 | BZ13: 4 | CA13: 4 | CB13: 4 | CC13: 4
A14: Associazione Pescatori | B14: Affitto barche | Y14: =Y11*$A$67+Y12*$A$68+Y13*$A$69 -> 100 | Z14: =Z11*$A$67+Z12*$A$68+Z13*$A$69 -> 100 | AA14: =AA11*$A$67+AA12*$A$68+AA13*$A$69 -> 100 | AB14: =AB11*$A$67+AB12*$A$68+AB13*$A$69 -> 100 | AC14: =AC11*$A$67+AC12*$A$68+AC13*$A$69 -> 100 | AD14: =AD11*$A$67+AD12*$A$68+AD13*$A$69 -> 100 | AE14: =AE11*$A$67+AE12*$A$68+AE13*$A$69 -> 100 | AF14: =AF11*$A$67+AF12*$A$68+AF13*$A$69 -> 100 | ... CC14: =CC11*$A$67+CC12*$A$68+CC13*$A$69 -> 250
B15: Offerte | Y15: 450 | Z15: =Y15-5 -> 445 | AA15: =Z15-5 -> 440 | AB15: =AA15-5 -> 435 | AC15: =AB15-5 -> 430 | AD15: =AC15-5 -> 425 | AE15: =AD15-5 -> 420 | AF15: =AE15-5 -> 415 | AG15: =AF15-5 -> 410 | ... CC15: =CB15-5 -> 170
B16: Assicurazione | Y16: =-(20*Y13+50*Y12+100*Y11) -> -80 | Z16: =-(20*Z13+50*Z12+100*Z11) -> -80 | AA16: =-(20*AA13+50*AA12+100*AA11) -> -80 | AB16: =-(20*AB13+50*AB12+100*AB11) -> -80 | AC16: =-(20*AC13+50*AC12+100*AC11) -> -80 | AD16: =-(20*AD13+50*AD12+100*AD11) -> -80 | AE16: =-(20*AE13+50*AE12+100*AE11) -> -80 | AF16: =-(20*AF13+50*AF12+100*AF11) -> -80 | ... CC16: =-(20*CC13+50*CC12+100*CC11) -> -180
AH17: prelievo Nic | AK17: prelievo Nic
B18: Spese e Movimenti | AH18: =-AH39 -> 0 | AK18: =-1000 -> -1000
B19: totale | X19: 0 | Y19: =X19+SUM(Y14:Y18) -> 470 | Z19: =Y19+SUM(Z14:Z18) -> 935 | AA19: =Z19+SUM(AA14:AA18) -> 1395 | AB19: =AA19+SUM(AB14:AB18) -> 1850 | AC19: =AB19+SUM(AC14:AC18) -> 2300 | AD19: =AC19+SUM(AD14:AD18) -> 2745 | AE19: =AD19+SUM(AE14:AE18) -> 3185 | AF19: =AE19+SUM(AF14:AF18) -> 3620 | ... CC19: =CB19+SUM(CC14:CC18) -> 20210
B21: Cibo | D21: 0 | E21: 0 | F21: 0 | G21: 0 | H21: 0 | I21: 0 | J21: 0 | K21: 0 | L21: 0 | M21: 0 | N21: 0 | O21: 0 | P21: 0 | Q21: 0 | R21: 0 | S21: 0 | T21: 0 | U21: 0 | V21: 0 | W21: 0 | X21: 0 | Y21: 0 | Z21: 0 | AA21: 0 | AB21: 0 | AC21: 0 | AD21: 0 | AE21: 0 | AF21: 0 | AG21: 0 | AH21: 0 | AI21: 0 | AJ21: 0 | AK21: 0 | AL21: 0 | AM21: 0 | AN21: 0 | AO21: 0 | AP21: 0 | AQ21: 0 | AR21: 0 | AS21: 0 | AT21: 0 | AU21: 0 | AV21: 0 | AW21: 0 | AX21: 0 | AY21: 0 | AZ21: 0 | BA21: 0 | BB21: 0 | BC21: 0 | BD21: 0 | BE21: 0 | BF21: 0 | BG21: 0 | BH21: 0 | BI21: 0 | BJ21: 0 | BK21: 0 | BL21: 0 | BM21: 0 | BN21: 0 | BO21: 0 | BP21: 0 | BQ21: 0 | BR21: 0 | BS21: 0 | BT21: 0 | BU21: 0 | BV21: 0 | BW21: 0 | BX21: 0 | BY21: 0 | BZ21: 0 | CA21: 0 | CB21: 0 | CC21: 0
B22: Affitto | D22: 0 | E22: 0 | F22: 0 | G22: 0 | H22: 0 | I22: 0 | J22: 0 | K22: 0 | L22: 0 | M22: 0 | N22: 0 | O22: 0 | P22: 0 | Q22: 0 | R22: 0 | S22: 0 | T22: 0 | U22: 0 | V22: 0 | W22: 0 | X22: 0 | Y22: 0 | Z22: 0 | AA22: 0 | AB22: 0 | AC22: 0 | AD22: 0 | AE22: 0 | AF22: 0 | AG22: 0 | AH22: 0 | AI22: 0 | AJ22: 0 | AK22: 0 | AL22: 0 | AM22: 0 | AN22: 0 | AO22: 0 | AP22: 0 | AQ22: 0 | AR22: 0 | AS22: 0 | AT22: 0 | AU22: 0 | AV22: 0 | AW22: 0 | AX22: 0 | AY22: 0 | AZ22: 0 | BA22: 0 | BB22: 0 | BC22: 0 | BD22: 0 | BE22: 0 | BF22: 0 | BG22: 0 | BH22: 0 | BI22: 0 | BJ22: 0 | BK22: 0 | BL22: 0 | BM22: 0 | BN22: 0 | BO22: 0 | BP22: 0 | BQ22: 0 | BR22: 0 | BS22: 0 | BT22: 0 | BU22: 0 | BV22: 0 | BW22: 0 | BX22: 0 | BY22: 0 | BZ22: 0 | CA22: 0 | CB22: 0 | CC22: 0
A23: Monaco (impiego)
B24: Salario da monaco + offerte | D24: =$A$61 -> 180 | E24: =$A$61 -> 180 | F24: =$A$61 -> 180 | G24: =$A$61 -> 180 | H24: =$A$61 -> 180 | I24: =$A$61 -> 180 | J24: =$A$61 -> 180 | K24: =$A$61 -> 180 | ... AP24: =$A$61 -> 180
B25: Studi monacali
B26: Funzionario locale | AQ26: 200 | AR26: 200 | AS26: 200 | AT26: 200 | AU26: 200 | AV26: 200 | AW26: 200 | AX26: 200 | AY26: 200 | AZ26: 200 | BA26: 200 | BB26: 200 | BC26: 200 | BD26: 200 | BE26: 200 | BF26: 200 | BG26: 200 | BH26: 200 | BI26: 200 | BJ26: 200 | BK26: 200 | BL26: 200 | BM26: 200 | BN26: 200 | BO26: 200 | BP26: 200 | BQ26: 200 | BR26: 200 | BS26: 200 | BT26: 200 | BU26: 200 | BV26: 200 | BW26: 200 | BX26: 1000 | BY26: 1000 | BZ26: 1000 | CA26: 1000 | CB26: 1000 | CC26: 1000
A27: Produzione di sake artigianale (business)
B28: Artigiano del sake | E28: =$A$62 -> 90 | F28: =$A$62 -> 90 | G28: =$A$62 -> 90 | H28: =$A$62 -> 90 | I28: =$A$62 -> 90 | J28: =$A$62 -> 90 | K28: =$A$62 -> 90 | L28: =$A$62 -> 90 | ... AG28: =$A$62 -> 90 | AK28: =$A$62 -> 90 | AL28: =$A$62 -> 90 | AM28: =$A$62 -> 90 | AN28: =$A$62 -> 90
B29: Vendita al tempio
B30: Attrezzi per il sake | E30: -150
B31: 🔒
A32: Impiegati Barca Grande
A33: 📜 | B33: Associazione
A34: 👤 | B34: Capitano | AK34: -1000 | AL34: -1000 | AM34: -1000 | AN34: -1000 | AO34: -1000 | AP34: -1000 | AQ34: -1000 | AR34: -1000 | AS34: -1000 | AT34: -1000 | AU34: -1000 | AV34: -1000 | AW34: -1000 | AX34: -1000 | AY34: -1000 | AZ34: -1000 | BA34: -1000 | BB34: -1000 | BC34: -1000 | BD34: -1000 | BE34: -1000 | BF34: -1000 | BG34: -1000 | BH34: -1000 | BI34: -1000 | BJ34: -1000 | BK34: -1000 | BL34: -1000 | BM34: -1000 | BN34: -1000 | BO34: -1000 | BP34: -1000 | BQ34: -1000 | BR34: -1000 | BS34: -1000 | BT34: -1000 | BU34: -1000 | BV34: -1000 | BW34: -1000 | BX34: -1000 | BY34: -1000 | BZ34: -1000 | CA34: -1000 | CB34: -1000 | CC34: -1000
A35: 👤 | B35: Nostromo (samurai) | AK35: -800 | AL35: -800 | AM35: -800 | AN35: -800 | AO35: -800 | AP35: -800 | AQ35: -800 | AR35: -800 | AS35: -800 | AT35: -800 | AU35: -800 | AV35: -800 | AW35: -800 | AX35: -800 | AY35: -800 | AZ35: -800 | BA35: -800 | BB35: -800 | BC35: -800 | BD35: -800 | BE35: -800 | BF35: -800 | BG35: -800 | BH35: -800 | BI35: -800 | BJ35: -800 | BK35: -800 | BL35: -800 | BM35: -800 | BN35: -800 | BO35: -800 | BP35: -800 | BQ35: -800 | BR35: -800 | BS35: -800 | BT35: -800 | BU35: -800 | BV35: -800 | BW35: -800 | BX35: -800 | BY35: -800 | BZ35: -800 | CA35: -800 | CB35: -800 | CC35: -800
A36: 👤 | B36: Navigatore | AK36: -700 | AL36: -700 | AM36: -700 | AN36: -700 | AO36: -700 | AP36: -700 | AQ36: -700 | AR36: -700 | AS36: -700 | AT36: -700 | AU36: -700 | AV36: -700 | AW36: -700 | AX36: -700 | AY36: -700 | AZ36: -700 | BA36: -700 | BB36: -700 | BC36: -700 | BD36: -700 | BE36: -700 | BF36: -700 | BG36: -700 | BH36: -700 | BI36: -700 | BJ36: -700 | BK36: -700 | BL36: -700 | BM36: -700 | BN36: -700 | BO36: -700 | BP36: -700 | BQ36: -700 | BR36: -700 | BS36: -700 | BT36: -700 | BU36: -700 | BV36: -700 | BW36: -700 | BX36: -700 | BY36: -700 | BZ36: -700 | CA36: -700 | CB36: -700 | CC36: -700
B37: Barca grande e molo (costi e introiti) | AG37: 1 barca grande | AH37: -6000 | AJ37: Molo | AK37: -2500
B38: Profitti vendite | AJ38: Pesca al largo (con volontari) | AK38: 2100 | AL38: 2100 | AM38: 2100 | AN38: 2100 | AO38: 2100 | AP38: 2100 | AQ38: 2100 | AR38: 2100 | AS38: 2100 | AT38: 2100 | AU38: 2100 | AV38: 2100 | AW38: 2100 | AX38: 2100 | AY38: 2100 | AZ38: 2100 | BA38: 2100 | BB38: 2100 | BC38: 2100 | BD38: 2100 | BE38: 2100 | BF38: 2100 | BG38: 2100 | BH38: 2100 | BI38: 2100 | BJ38: 2100 | BK38: 2100 | BL38: 2100 | BM38: 2100 | BN38: 2100 | BO38: 2100 | BP38: 2100 | BQ38: 2100 | BR38: 2100 | BS38: 2100 | BT38: 2100 | BU38: 2100 | BV38: 2100 | BW38: 2100 | BX38: 2100 | BY38: 2100 | BZ38: 2100 | CA38: 2100 | CB38: 2100 | CC38: 2100
B39: Movimenti | AJ39: Daimyoo supporto momentaneo | AK39: =ABS(SUM(AK34:AK36))*0.5 -> 1250 | AL39: =ABS(SUM(AL34:AL36))*0.5 -> 1250 | AM39: =ABS(SUM(AM34:AM36))*0.5 -> 1250 | AN39: =ABS(SUM(AN34:AN36))*0.5 -> 1250 | AO39: =ABS(SUM(AO34:AO36))*0.5 -> 1250 | AP39: =ABS(SUM(AP34:AP36))*0.5 -> 1250 | AQ39: =ABS(SUM(AQ34:AQ36))*0.5 -> 1250 | AR39: =ABS(SUM(AR34:AR36))*0.5 -> 1250 | ... CC39: =ABS(SUM(CC34:CC36))*0.5 -> 1250
A40: Hobbies
B41: Tiro con l'arco | U41: premio | V41: 50
...

Sheet Cris
B1: Cris | D1: Aprile | E1: Maggio | F1: Giugno | G1: Luglio | H1: Agosto | I1: Settembre | J1: Ottobre | K1: Novembre | L1: Dicembre | M1: Gennaio | N1: Febbraio | O1: Marzo | P1: Aprile | Q1: Maggio | R1: Giugno | S1: Luglio | T1: Agosto | U1: Settembre | V1: Ottobre | W1: Novembre | X1: Dicembre | Y1: Gennaio | Z1: Febbraio | AA1: Marzo | AB1: Aprile | AC1: Maggio | AD1: Giugno | AE1: Luglio | AF1: Agosto | AG1: Settembre | AH1: Ottobre | AI1: Novembre | AJ1: Dicembre | AK1: Gennaio | AL1: Febbraio | AM1: Marzo | AN1: Aprile | AO1: Maggio | AP1: Giugno | AQ1: Luglio | AR1: Agosto | AS1: Settembre | AT1: Ottobre | AU1: Novembre | AV1: Dicembre | AW1: Gennaio | AX1: Febbraio | AY1: Marzo | AZ1: Aprile | BA1: Maggio | BB1: Giugno | BC1: Luglio | BD1: Agosto | BE1: Settembre | BF1: Ottobre | BG1: Novembre | BH1: Dicembre | BI1: Gennaio | BJ1: Febbraio | BK1: Marzo | BL1: Aprile | BM1: Maggio | BN1: Giugno | BO1: Luglio | BP1: Agosto | BQ1: Settembre | BR1: Ottobre | BS1: Novembre | BT1: Dicembre | BU1: Gennaio | BV1: Febbraio | BW1: Marzo | BX1: Aprile | BY1: Maggio | BZ1: Giugno | CA1: Luglio | CB1: Agosto | CC1: Settembre | CD1: Ottobre | CE1: Novembre | CF1: Dicembre | CG1: Gennaio | CH1: Febbraio | CI1: Marzo | CJ1: Aprile | CK1: Maggio | CL1: Giugno | CM1: Luglio | CN1: Agosto | CO1: Settembre | CP1: Ottobre | CQ1: Novembre | CR1: Dicembre
B2: Anno | D2: 1532 | E2: =D2+IF(E1="Gennaio",1,0) -> 1532 | F2: =E2+IF(F1="Gennaio",1,0) -> 1532 | G2: =F2+IF(G1="Gennaio",1,0) -> 1532 | H2: =G2+IF(H1="Gennaio",1,0) -> 1532 | I2: =H2+IF(I1="Gennaio",1,0) -> 1532 | J2: =I2+IF(J1="Gennaio",1,0) -> 1532 | K2: =J2+IF(K1="Gennaio",1,0) -> 1532 | L2: =K2+IF(L1="Gennaio",1,0) -> 1532 | ... CR2: =CQ2+IF(CR1="Gennaio",1,0) -> 1539
B3: Mese in-game | D3: =C3+1 -> 1 | E3: =D3+1 -> 2 | F3: =E3+1 -> 3 | G3: =F3+1 -> 4 | H3: =G3+1 -> 5 | I3: =H3+1 -> 6 | J3: =I3+1 -> 7 | K3: =J3+1 -> 8 | ... CR3: =CQ3+1 -> 93
A5: =MAX(D8:CC8) -> 4110 | B5: AV | C5: =ABS(C34) -> 700 | D5: =ABS(D23) -> 35 | E5: =ABS(E18+E19) -> 1020 | AB5: =ABS(AB33+AB34+AB31) -> 8350 | AE5: =-AE31 -> 500
A6: =MIN(D8:CC8) -> -7770 | B6: NAV | D6: =SUM($C5:D5)+D7 -> 4235 | E6: =SUM($C5:E5)+E7 -> 4514 | F6: =SUM($C5:F5)+F7 -> 4803 | G6: =SUM($C5:G5)+G7 -> 5156 | H6: =SUM($C5:H5)+H7 -> 5492 | I6: =SUM($C5:I5)+I7 -> 5833 | J6: =SUM($C5:J5)+J7 -> 6147 | K6: =SUM($C5:K5)+K7 -> 6465 | ... CC6: =SUM($C5:CC5)+CC7 -> 67088
B7: Liquidi | C7: =SUM(C11:C1048576) -> 4300 | D7: =C7+SUM(D11:D40) -> 3500 | E7: =D7+SUM(E11:E40) -> 2759 | F7: =E7+SUM(F11:F40) -> 3048 | G7: =F7+SUM(G11:G40) -> 3401 | H7: =G7+SUM(H11:H40) -> 3737 | I7: =H7+SUM(I11:I40) -> 4078 | J7: =I7+SUM(J11:J40) -> 4392 | K7: =J7+SUM(K11:K40) -> 4710 | ... CC7: =CB7+SUM(CC11:CC40) -> 56483
B8: Profitto netto | D8: =D7-C7 -> -800 | E8: =E7-D7 -> -741 | F8: =F7-E7 -> 289 | G8: =G7-F7 -> 353 | H8: =H7-G7 -> 336 | I8: =I7-H7 -> 341 | J8: =J7-I7 -> 314 | K8: =K7-J7 -> 318 | ... CC8: =CC7-CB7 -> 3483
A9: Terreni | B9: terreno edificabile a ovest [Kawa] | C9: 100 | D9: 100 | E9: =D9 -> 100 | F9: =E9 -> 100 | G9: =F9 -> 100 | H9: =G9 -> 100 | I9: =H9 -> 100 | J9: =I9 -> 100 | K9: =J9 -> 100 | L9: =K9 -> 100 | ... CC9: =CB9 -> 100
A10: Barche | B10: barca piccola | C10: 1 | D10: 1 | E10: 1 | F10: 1 | G10: 1 | H10: 1 | I10: 1 | J10: 1 | K10: 1 | L10: 1 | M10: 1 | N10: 1 | O10: 1 | P10: 1 | Q10: 1 | R10: 1 | S10: 1 | T10: 1 | U10: 1 | V10: 1 | W10: 1 | X10: 1 | Y10: 1 | Z10: 1 | AA10: 1 | AB10: 1 | AC10: 1 | AD10: 1 | AE10: 1 | AF10: 1 | AG10: 1 | AH10: 1 | AI10: 1 | AJ10: 1 | AK10: 1 | AL10: 1 | AM10: 1 | AN10: 1 | AO10: 1 | AP10: 1 | AQ10: 1 | AR10: 1 | AS10: 1 | AT10: 1 | AU10: 1 | AV10: 1 | AW10: 1 | AX10: 1 | AY10: 1 | AZ10: 1 | BA10: 1 | BB10: 1 | BC10: 1 | BD10: 1 | BE10: 1 | BF10: 1 | BG10: 1 | BH10: 1 | BI10: 1 | BJ10: 1 | BK10: 1 | BL10: 1 | BM10: 1 | BN10: 1 | BO10: 1 | BP10: 1 | BQ10: 1 | BR10: 1 | BS10: 1 | BT10: 1 | BU10: 1 | BV10: 1 | BW10: 1 | BX10: 1 | BY10: 1 | BZ10: 1 | CA10: 1 | CB10: 1 | CC10: 1
B11: Cibo | D11: -250 | E11: -250 | F11: -250 | G11: -250 | H11: -250 | I11: -250 | J11: -250 | K11: -250 | L11: -250 | M11: -250 | N11: -250 | O11: -250 | P11: -250 | Q11: -250 | R11: -250 | S11: -250 | T11: -250 | U11: -250 | V11: -250 | W11: -250 | X11: -250 | Y11: -250 | Z11: -250 | AA11: -250 | AB11: -250 | AC11: -250 | AD11: -250 | AE11: -250 | AF11: -250 | AG11: -250 | AH11: -250 | AI11: -250 | AJ11: -250 | AK11: -250 | AL11: -250 | AM11: -250 | AN11: -250 | AO11: -250 | AP11: -250 | AQ11: -250 | AR11: -250 | AS11: -250 | AT11: -250 | AU11: -250 | AV11: -250 | AW11: -250 | AX11: -250 | AY11: -250 | AZ11: -250 | BA11: -250 | BB11: -250 | BC11: -250 | BD11: -250 | BE11: -250 | BF11: -250 | BG11: -250 | BH11: -250 | BI11: -250 | BJ11: -250 | BK11: -250 | BL11: -250 | BM11: -250 | BN11: -250 | BO11: -250 | BP11: -250 | BQ11: -250 | BR11: -250 | BS11: -250 | BT11: -250 | BU11: -250 | BV11: -250 | BW11: -250 | BX11: -250 | BY11: -250 | BZ11: -250 | CA11: -250 | CB11: -250 | CC11: -250
B12: Affitto | D12: -50 | E12: -50
A13: Pescatore
B14: Pesca | E14: =$A$41 -> 425 | F14: =$A$41 -> 425 | G14: =$A$41 -> 425 | H14: =$A$41 -> 425 | I14: =$A$41 -> 425 | J14: =$A$41 -> 425 | K14: =$A$41 -> 425 | L14: =$A$41 -> 425 | M14: =$A$43 -> 575 | N14: =$A$43 -> 575 | O14: =$A$43 -> 575 | P14: =$A$43 -> 575 | Q14: =$A$43 -> 575 | R14: =$A$43 -> 575 | S14: =$A$43 -> 575 | T14: =$A$43 -> 575 | ... X14: =$A$43 -> 575
B15: Tassa porto | D15: =-$A$46 -> -20 | E15: =-$A$46 -> -20 | F15: =-$A$46 -> -20 | G15: =-$A$46 -> -20 | H15: =-$A$46 -> -20 | I15: =-$A$46 -> -20 | J15: =-$A$46 -> -20 | K15: =-$A$46 -> -20 | ... CC15: =-$A$46 -> -20
B16: Bancarella
A17: 📜 | B17: Tassa bancarella | D17: =-$A$47 -> -25 | E17: =-$A$47 -> -25 | F17: =-$A$47 -> -25 | G17: =-$A$47 -> -25 | H17: =-$A$47 -> -25 | I17: =-$A$47 -> -25 | J17: =-$A$47 -> -25 | K17: =-$A$47 -> -25 | ... X17: =-$A$47 -> -25
B18: 2 reti da pesca | E18: -20
A19: 📜 | B19: Barca da pesca | D19: barca | E19: -1000
A20: Taglialegna
B21: Taglialegna | E21: 249 | F21: 209 | G21: 243 | H21: 256 | I21: 261 | J21: 234 | K21: 238 | L21: 237
B22: Permesso tagliare legna | D22: 0 | E22: 0 | F22: 0 | G22: 0 | H22: 0 | I22: 0 | J22: 0 | K22: 0 | L22: 0
B23: ascia, machete | D23: -35
A24: Guardia
A25: ⭐️ | B25: guardia allevamento Granchi Kanemura | Y25: 900 | Z25: 900 | AA25: 900 | AB25: 900 | AC25: 900 | AD25: 900 | AE25: 1100 | AF25: 1100 | AG25: 1100 | AH25: 1100 | AI25: 1100 | AJ25: 1100 | AK25: 1100 | AL25: 1100 | AM25: 1100 | AN25: 1100 | AO25: 1100 | AP25: 1100 | AQ25: 1100 | AR25: 1100 | AS25: 1100 | AT25: 1100 | AU25: 1100 | AV25: 1100 | AW25: 1100 | AX25: 1100 | AY25: 1100 | AZ25: 1100 | BA25: 1100 | BB25: 1100 | BC25: 1100 | BD25: 1100 | BE25: 1100 | BF25: 1100 | BG25: 1100 | BH25: 1100 | BI25: 1300 | BJ25: 1300 | BK25: 1300 | BL25: 1300 | BM25: 1300 | BN25: 1300 | BO25: 1300 | BP25: 1300 | BQ25: 1300 | BR25: 1300 | BS25: 1300 | BT25: 1300 | BU25: 1300 | BV25: 1300 | BW25: 1300 | BX25: 1300 | BY25: 1300 | BZ25: 1300 | CA25: 1301 | CB25: 1302 | CC25: 1303
A26: Altre tasse | B26: Tassa terreno edificabile | E26: =-$A$45*E9 -> -50 | F26: =-$A$45*F9 -> -50 | G26: =-$A$45*G9 -> -50 | H26: =-$A$45*H9 -> -50 | I26: =-$A$45*I9 -> -50 | J26: =-$A$45*J9 -> -50 | K26: =-$A$45*K9 -> -50 | L26: =-$A$45*L9 -> -50 | ... CC26: =-$A$45*CC9 -> -50
A29: {=SUM(COUNTIF(A13:A25, {"📜","👤"})) & "/10 Permessi"} -> 2/10 Permessi | BU29: vende a Daichi | BV29: 300
C30: Bottino di partenza | AJ30: missione | AK30: 150
C31: 5000 | AA31: Casa a nord-est | AB31: =-6000-1500-500 -> -8000 | AD31: katana 931 | AE31: -500 | CB31: premio Daimyo | CC31: =10000/4 -> 2500
C33: 100 Kawa di terreno boschivo non-edificabile | D33: artigiano per costruire la casetta | G33: consegna casse | O33: samurai | X33: piccolo lingotto d'oro | AA33: Armatura da samurai | AB33: -300 | AD33: scatola del relitto | AE33: 300
C34: =-700 -> -700 | D34: -400 | G34: 30 | O34: 300 | X34: specchio da viaggio finemente decorato | AA34: 2 completi vestiti | AB34: -50 | AD34: piccolo lingotto | AE34: 3500
X35: Maschera da Cerimonia bianca finemente decorata
D36: bonifica bosco | O36: vende perle | AD36: mancia di netsuki | AE36: 30
D37: -20 | O37: =100 * 5 * 6 -> 3000
A41: 425 | B41: Pescatore (barca piccola)
A42: 500 | B42: Pescatore (barca media)
A43: 575 | B43: Pescatore (barca grande)
A44: 240 | B44: Taglialegna
A45: 0.5 | B45: tassa terreno edificabile $/kawa
A46: 20 | B46: Tassa porto
A47: 25 | B47: Tassa bancarella

Sheet Peter
B1: Peter | D1: Aprile | E1: Maggio | F1: Giugno | G1: Luglio | H1: Agosto | I1: Settembre | J1: Ottobre | K1: Novembre | L1: Dicembre | M1: Gennaio | N1: Febbraio | O1: Marzo | P1: Aprile | Q1: Maggio | R1: Giugno | S1: Luglio | T1: Agosto | U1: Settembre | V1: Ottobre | W1: Novembre | X1: Dicembre | Y1: Gennaio | Z1: Febbraio | AA1: Marzo | AB1: Aprile | AC1: Maggio | AD1: Giugno | AE1: Luglio | AF1: Agosto | AG1: Settembre | AH1: Ottobre | AI1: Novembre | AJ1: Dicembre | AK1: Gennaio | AL1: Febbraio | AM1: Marzo | AN1: Aprile | AO1: Maggio | AP1: Giugno | AQ1: Luglio | AR1: Agosto | AS1: Settembre | AT1: Ottobre | AU1: Novembre | AV1: Dicembre | AW1: Gennaio | AX1: Febbraio | AY1: Marzo | AZ1: Aprile | BA1: Maggio | BB1: Giugno | BC1: Luglio | BD1: Agosto | BE1: Settembre | BF1: Ottobre | BG1: Novembre | BH1: Dicembre | BI1: Gennaio | BJ1: Febbraio | BK1: Marzo | BL1: Aprile | BM1: Maggio | BN1: Giugno | BO1: Luglio | BP1: Agosto | BQ1: Settembre | BR1: Ottobre | BS1: Novembre | BT1: Dicembre | BU1: Gennaio | BV1: Febbraio | BW1: Marzo | BX1: Aprile | BY1: Maggio | BZ1: Giugno | CA1: Luglio | CB1: Agosto | CC1: Settembre | CD1: Ottobre | CE1: Novembre | CF1: Dicembre | CG1: Gennaio | CH1: Febbraio | CI1: Marzo | CJ1: Aprile | CK1: Maggio | CL1: Giugno | CM1: Luglio | CN1: Agosto | CO1: Settembre | CP1: Ottobre | CQ1: Novembre | CR1: Dicembre
B2: Anno | D2: 1532 | E2: =D2+IF(E1="Gennaio",1,0) -> 1532 | F2: =E2+IF(F1="Gennaio",1,0) -> 1532 | G2: =F2+IF(G1="Gennaio",1,0) -> 1532 | H2: =G2+IF(H1="Gennaio",1,0) -> 1532 | I2: =H2+IF(I1="Gennaio",1,0) -> 1532 | J2: =I2+IF(J1="Gennaio",1,0) -> 1532 | K2: =J2+IF(K1="Gennaio",1,0) -> 1532 | L2: =K2+IF(L1="Gennaio",1,0) -> 1532 | ... CR2: =CQ2+IF(CR1="Gennaio",1,0) -> 1539
B3: Mese in-game | D3: =C3+1 -> 1 | E3: =D3+1 -> 2 | F3: =E3+1 -> 3 | G3: =F3+1 -> 4 | H3: =G3+1 -> 5 | I3: =H3+1 -> 6 | J3: =I3+1 -> 7 | K3: =J3+1 -> 8 | ... CR3: =CQ3+1 -> 93
AH4: todo increase income | AN4: =SUMIF(AN11:AN39, ">=0") -> 4608
A5: =MAX(D8:CC8) -> 2224.76 | B5: AV | C5: =ABS(C51) -> 230 | D5: =ABS(D16+D51) -> 1400 | G5: =ABS(G20) -> 900 | J5: =ABS(J24) -> 900 | M5: =ABS(M32+M51) -> 5120 | Y5: =-Y28 -> 2700 | AG5: =ABS(SUM(Y53:AG53)) -> 27500 | AQ5: 100 | BX5: -5000 | BZ5: =12000+14000 -> 26000 | CA5: =ABS(CA50+CA53+CA57) -> 8206.66
A6: =MIN(D8:CC8) -> -24325.24 | B6: NAV | D6: =SUM($C5:D5)+D7 -> 5427 | E6: =SUM($C5:E5)+E7 -> 5914 | F6: =SUM($C5:F5)+F7 -> 6401 | G6: =SUM($C5:G5)+G7 -> 7133.2 | H6: =SUM($C5:H5)+H7 -> 7865.4 | I6: =SUM($C5:I5)+I7 -> 8597.6 | J6: =SUM($C5:J5)+J7 -> 9600 | K6: =SUM($C5:K5)+K7 -> 11602.4 | ... AA6: =SUM($C5:AA5)+AA7 -> 21042.533 | AB6: =SUM($C5:AA5)+AB7 -> 19823.858 | AC6: =SUM($C5:AC5)+AC7 -> 18705.182 | AD6: =SUM($C5:AD5)+AD7 -> 17586.507 | AE6: =SUM($C5:AD5)+AE7 -> 16079.311 | AF6: =SUM($C5:AF5)+AF7 -> 14272.116 | AG6: =SUM($C5:AG5)+AG7 -> 40131.32 | AH6: =SUM($C5:AH5)+AH7 -> 41321.08 | AI6: =SUM($C5:AI5)+AI7 -> 41925.84 | AJ6: =SUM($C5:AJ5)+AJ7 -> 42800.6 | AK6: =SUM($C5:AK5)+AK7 -> 43725.36 | AL6: =SUM($C5:AL5)+AL7 -> 44650.12 | AM6: =SUM($C5:AM5)+AM7 -> 45624.88 | ... CC6: =SUM($C5:CC5)+CC7 -> 84642.46
B7: Liquidi | C7: =SUM(C9:C1048576) -> 4770 | D7: =C7+SUM(D9:D1048576) -> 3797 | E7: =D7+SUM(E9:E1048576) -> 4284 | F7: =E7+SUM(F9:F1048576) -> 4771 | G7: =F7+SUM(G9:G1048576) -> 4603.2 | H7: =G7+SUM(H9:H1048576) -> 5335.4 | I7: =H7+SUM(I9:I1048576) -> 6067.6 | J7: =I7+SUM(J9:J1048576) -> 6170 | K7: =J7+SUM(K9:K1048576) -> 8172.4 | ... CC7: =CB7+SUM(CC9:CC1048576) -> 16585.8
B8: Profitto netto | D8: =D7-C7 -> -973 | E8: =E7-D7 -> 487 | F8: =F7-E7 -> 487 | G8: =G7-F7 -> -167.8 | H8: =H7-G7 -> 732.2 | I8: =I7-H7 -> 732.2 | J8: =J7-I7 -> 102.4 | K8: =K7-J7 -> 2002.4 | ... CC8: =CC7-CB7 -> 2204.56
B9: Cibo | D9: -270 | E9: -270 | F9: -270 | G9: -270 | H9: -270 | I9: -270 | J9: -270 | K9: -270 | L9: -270 | M9: -270 | N9: -270 | O9: -270 | P9: -270 | Q9: -270 | R9: -270 | S9: -270 | T9: -270 | U9: -270 | V9: -270 | W9: -270 | X9: -270 | Y9: -270 | Z9: -270 | AA9: -270 | AB9: -270 | AC9: -270 | AD9: -270 | AE9: -270 | AF9: -270 | AG9: -270 | AH9: -270 | AI9: -270 | AJ9: -270 | AK9: -270 | AL9: -270 | AM9: -270 | AN9: -270 | AO9: -270 | AP9: -270 | AQ9: -270 | AR9: -270 | AS9: -270 | AT9: -270 | AU9: -270 | AV9: -270 | AW9: -270 | AX9: -270 | AY9: -270 | AZ9: -270 | BA9: -270 | BB9: -270 | BC9: -270 | BD9: -270 | BE9: -270 | BF9: -270 | BG9: -270 | BH9: -270 | BI9: -270 | BJ9: -270 | BK9: -270 | BL9: -270 | BM9: -270 | BN9: -270 | BO9: -270 | BP9: -270 | BQ9: -270 | BR9: -270 | BS9: -270 | BT9: -270 | BU9: -270 | BV9: -270 | BW9: -270 | BX9: -270 | BY9: -270 | BZ9: -270 | CA9: -270 | CB9: -270 | CC9: -270
B10: Affitto | D10: -160 | E10: -160 | F10: -160 | G10: -160 | H10: -160 | I10: -160 | J10: -160 | K10: -160 | L10: -160 | M10: -160 | N10: -160 | O10: -160 | P10: -160 | Q10: -160 | R10: -160 | S10: -160 | T10: -160 | U10: -160 | V10: -160 | W10: -160 | X10: -160 | Y10: -160 | Z10: -160 | AA10: -160 | AB10: -160 | AC10: -160 | AD10: -160 | AE10: -160 | AF10: -160 | AG10: -160 | AH10: -160 | AI10: -160 | AJ10: -160 | AK10: -160 | AL10: -160 | AM10: -160 | AN10: -160 | AO10: -160 | AP10: -160 | AQ10: -160 | AR10: -160 | AS10: -160 | AT10: -160 | AU10: -160 | AV10: -160 | AW10: -160 | AX10: -160 | AY10: -160 | AZ10: -160 | BA10: -160 | BB10: -160 | BC10: -160 | BD10: -160 | BE10: -160 | BF10: -160 | BG10: -160 | BH10: -160 | BI10: -160 | BJ10: -160 | BK10: -160 | BL10: -160 | BM10: -160 | BN10: -160 | BO10: -160 | BP10: -160 | BQ10: -160 | BR10: -160 | BS10: -160 | BT10: -160 | BU10: -160 | BV10: -160 | BW10: -160 | BX10: -160 | BY10: -160 | BZ10: -160 | CA10: -160 | CB10: -160 | CC10: -160
A11: Tratta 1 (K-H-T) | B11: =SUM(D11:BZ16) -> 85980 | D11: =$A$59 -> 1100 | E11: =$A$59 -> 1100 | F11: =$A$59 -> 1100 | G11: =$A$59 -> 1100 | H11: =$A$59 -> 1100 | I11: =$A$59 -> 1100 | J11: =$A$59 -> 1100 | K11: =$A$59 -> 1100 | ... CC11: =$A$59 -> 1100
A12: 📜 | B12: Tassa rotta commerciale | D12: =-$A$66 -> -100 | E12: =-$A$66 -> -100 | F12: =-$A$66 -> -100 | G12: =-$A$66 -> -100 | H12: =-$A$66 -> -100 | I12: =-$A$66 -> -100 | J12: =-$A$66 -> -100 | K12: =-$A$66 -> -100 | ... CC12: =-$A$66 -> -100
A13: ⭐️ | B13: Burocrate
A14: 👤 | B14: Apprendista mercante | S14: =$A$59*$A$61 -> 660 | T14: =$A$59*$A$61 -> 660 | U14: =$A$59*$A$61 -> 660 | V14: =$A$59*$A$61 -> 660 | W14: =$A$59*$A$61 -> 660 | X14: =$A$59*$A$61 -> 660 | Y14: =$A$59*$A$61 -> 660 | Z14: =$A$59*$A$61 -> 660 | ... BH14: =$A$59*$A$61 -> 660 | BI14: =BH14 -> 660 | BJ14: =BI14 -> 660 | BK14: =BJ14 -> 660 | BL14: =BK14 -> 660 | BM14: =BL14 -> 660 | BN14: =BM14 -> 660 | BO14: =BN14 -> 660 | BP14: =BO14 -> 660 | ... BZ14: =BY14 -> 660
B15: salario | S15: =-$A$60 -> -270 | T15: =-$A$60 -> -270 | U15: =-$A$60 -> -270 | V15: =-$A$60 -> -270 | W15: =-$A$60 -> -270 | X15: =-$A$60 -> -270 | Y15: =-$A$60 -> -270 | Z15: =-$A$60 -> -270 | ... AD15: =-$A$60 -> -270 | AE15: -400 | AF15: -400 | AG15: -400 | AH15: -440 | AI15: -480 | AJ15: -520 | AK15: -520 | AL15: -520 | AM15: -520 | AN15: -520 | AO15: -520 | AP15: -520 | AQ15: -520 | AR15: -520 | AS15: -520 | AT15: -520 | AU15: -520 | AV15: -520 | AW15: -520 | AX15: -520 | AY15: -520 | AZ15: -520 | BA15: -520 | BB15: -520 | BC15: -520 | BD15: -520 | BE15: -520 | BF15: -520 | BG15: -520 | BH15: -520 | BI15: -520 | BJ15: -520 | BK15: -520 | BL15: -520 | BM15: -520 | BN15: -520 | BO15: =BN15 -> -520 | BP15: =BO15 -> -520 | BQ15: =BP15 -> -520 | BR15: =BQ15 -> -520 | BS15: =BR15 -> -520 | BT15: =BS15 -> -520 | BU15: =BT15 -> -520 | BV15: =BU15 -> -520 | ... BZ15: =BY15 -> -520
B16: Carro, cavallo, barili | D16: -900 | AN16: todo boost profitti Hirata
A17: Tratta 2 (U-H-K) | B17: =SUM(D17:BZ20) -> 8460 | G17: =$A$59*$A$61 -> 660 | H17: =$A$59*$A$61 -> 660 | I17: =$A$59*$A$61 -> 660 | J17: =$A$59*$A$61 -> 660 | K17: =$A$59*$A$61 -> 660 | L17: =$A$59*$A$61 -> 660 | M17: =$A$59*$A$61 -> 660 | N17: =$A$59*$A$61 -> 660 | ... BH17: =$A$59*$A$61 -> 660 | BI17: =BH17 -> 660 | BJ17: =BI17 -> 660 | BK17: =BJ17 -> 660 | BL17: =BK17 -> 660 | BM17: =BL17 -> 660 | BN17: =BM17 -> 660 | BO17: =BN17 -> 660 | BP17: =BO17 -> 660 | ... CC17: =CB17 -> 660
A18: 📜 | B18: Tassa rotta commerciale | G18: =- $A$66 -> -100 | H18: =- $A$66 -> -100 | I18: =- $A$66 -> -100 | J18: =- $A$66 -> -100 | K18: =- $A$66 -> -100 | L18: =- $A$66 -> -100 | M18: =- $A$66 -> -100 | N18: =- $A$66 -> -100 | ... CC18: =- $A$66 -> -100
A19: 👤 | B19: Apprendista mercante | G19: =-$A$60 -> -270 | H19: =-$A$60 -> -270 | I19: =-$A$60 -> -270 | J19: =-$A$60 -> -270 | K19: =-$A$60 -> -270 | L19: =-$A$60 -> -270 | M19: =-$A$60 -> -270 | N19: =-$A$60 -> -270 | ... AD19: =-$A$60 -> -270 | AE19: -400 | AF19: -400 | AG19: -400 | AH19: -440 | AI19: -480 | AJ19: -520 | AK19: -520 | AL19: -520 | AM19: -520 | AN19: -520 | AO19: -520 | AP19: -520 | AQ19: -520 | AR19: -520 | AS19: -520 | AT19: -520 | AU19: -520 | AV19: -520 | AW19: -520 | AX19: -520 | AY19: -520 | AZ19: -520 | BA19: -520 | BB19: -520 | BC19: -520 | BD19: -520 | BE19: -520 | BF19: -520 | BG19: -520 | BH19: -520 | BI19: -520 | BJ19: -520 | BK19: -520 | BL19: -520 | BM19: -520 | BN19: -520 | BO19: -520 | BP19: -520 | BQ19: -520 | BR19: -520 | BS19: -520 | BT19: -520 | BU19: -520 | BV19: =BU19 -> -520 | BW19: =BV19 -> -520 | BX19: =BW19 -> -520 | BY19: =BX19 -> -520 | BZ19: =BY19 -> -520 | CA19: =BZ19 -> -520 | CB19: =CA19 -> -520 | CC19: =CB19 -> -520
B20: Carro, cavallo, barili | G20: -900
A21: Tratta 3 (T-H-K) | B21: =SUM(D21:BZ24) -> 7590 | J21: =$A$59*$A$61 -> 660 | K21: =$A$59*$A$61 -> 660 | L21: =$A$59*$A$61 -> 660 | M21: =$A$59*$A$61 -> 660 | N21: =$A$59*$A$61 -> 660 | O21: =$A$59*$A$61 -> 660 | P21: =$A$59*$A$61 -> 660 | Q21: =$A$59*$A$61 -> 660 | ... BI21: =$A$59*$A$61 -> 660 | BJ21: =BI21 -> 660 | BK21: =BJ21 -> 660 | BL21: =BK21 -> 660 | BM21: =BL21 -> 660 | BN21: =BM21 -> 660 | BO21: =BN21 -> 660 | BP21: =BO21 -> 660 | BQ21: =BP21 -> 660 | ... CC21: =CB21 -> 660
A22: 📜 | B22: Tassa rotta commerciale | J22: =- $A$66 -> -100 | K22: =- $A$66 -> -100 | L22: =- $A$66 -> -100 | M22: =- $A$66 -> -100 | N22: =- $A$66 -> -100 | O22: =- $A$66 -> -100 | P22: =- $A$66 -> -100 | Q22: =- $A$66 -> -100 | ... CC22: =- $A$66 -> -100
A23: 👤 | B23: Apprendista mercante | J23: =-$A$60 -> -270 | K23: =-$A$60 -> -270 | L23: =-$A$60 -> -270 | M23: =-$A$60 -> -270 | N23: =-$A$60 -> -270 | O23: =-$A$60 -> -270 | P23: =-$A$60 -> -270 | Q23: =-$A$60 -> -270 | ... AD23: =-$A$60 -> -270 | AE23: -400 | AF23: -400 | AG23: -400 | AH23: -440 | AI23: -480 | AJ23: -520 | AK23: =AJ23 -> -520 | AL23: =AK23 -> -520 | AM23: =AL23 -> -520 | AN23: =AM23 -> -520 | AO23: =AN23 -> -520 | AP23: =AO23 -> -520 | AQ23: =AP23 -> -520 | AR23: =AQ23 -> -520 | ... CC23: =CB23 -> -520
B24: Carro, cavallo, barili | J24: -900
A25: Tratta 4 Marittima (T-H-K) | B25: =SUM(D25:BZ28) -> 11560 | Y25: =$A$67 -> 700 | Z25: =$A$67 -> 700 | AA25: =$A$67 -> 700 | AB25: =$A$67 -> 700 | AC25: =$A$67 -> 700 | AD25: =$A$67 -> 700 | AE25: =$A$67*1.1 -> 770 | AF25: =$A$67*1.1 -> 770 | AG25: 870 | AH25: =AG25 -> 870 | AI25: =AH25 -> 870 | AJ25: =AI25 -> 870 | AK25: =AJ25 -> 870 | AL25: =AK25 -> 870 | AM25: =AL25 -> 870 | AN25: =AM25 -> 870 | AO25: =AN25 -> 870 | ... CC25: =CB25 -> 870
A26: 📜 | B26: Tassa rotta commerciale (barca media) | Y26: =- $A$66 -> -100 | Z26: =- $A$66 -> -100 | AA26: =- $A$66 -> -100 | AB26: =- $A$66 -> -100 | AC26: =- $A$66 -> -100 | AD26: =- $A$66 -> -100 | AE26: =- $A$66 -> -100 | AF26: =- $A$66 -> -100 | ... CC26: =- $A$66 -> -100
A27: 👤 | B27: Apprendista mercante | Y27: =-$A$60 -> -270 | Z27: =-$A$60 -> -270 | AA27: =-$A$60 -> -270 | AB27: =-$A$60 -> -270 | AC27: =-$A$60 -> -270 | AD27: =-$A$60 -> -270 | AE27: -400 | AF27: -400 | AG27: -400 | AH27: -440 | AI27: -480 | AJ27: -520 | AK27: -520 | AL27: -520 | AM27: -520 | AN27: -520 | AO27: -520 | AP27: -520 | AQ27: -520 | AR27: -520 | AS27: -520 | AT27: -520 | AU27: -520 | AV27: -520 | AW27: -520 | AX27: -520 | AY27: -520 | AZ27: -520 | BA27: -520 | BB27: -520 | BC27: -520 | BD27: -520 | BE27: -520 | BF27: -520 | BG27: -520 | BH27: -520 | BI27: -520 | BJ27: -520 | BK27: -520 | BL27: -520 | BM27: -520 | BN27: -520 | BO27: -520 | BP27: -520 | BQ27: -520 | BR27: -520 | BS27: -520 | BT27: -520 | BU27: -520 | BV27: =BU27 -> -520 | BW27: =BV27 -> -520 | BX27: =BW27 -> -520 | BY27: =BX27 -> -520 | BZ27: =BY27 -> -520 | CA27: =BZ27 -> -520 | CB27: =CA27 -> -520 | CC27: =CB27 -> -520
B28: Barca e attrezzi | Y28: -2700
A29: Magazzino piccolo a Hakusui (rotte 1, 2, 3) | B29: =SUM(D29:BZ32) -> 7956
A30: 📜 | B30: Boost vendite | M30: =(M11+M17+M21)*$A$62 -> 484 | N30: =(N11+N17+N21)*$A$62 -> 484 | O30: =(O11+O17+O21)*$A$62 -> 484 | P30: =(P11+P17+P21)*$A$62 -> 484 | Q30: =(Q11+Q17+Q21)*$A$62 -> 484 | R30: =(R11+R17+R21)*$A$62 -> 484 | S30: =(S11+S17+S21)*$A$62 -> 484 | T30: =(T11+T17+T21)*$A$62 -> 484 | ... X30: =(X11+X17+X21)*$A$62 -> 484 | Y30: =(Y11+Y17+Y21+Y25)*$A$62 -> 624 | Z30: =(Z11+Z17+Z21+Z25)*$A$62 -> 624 | AA30: =(AA11+AA17+AA21+AA25)*$A$62 -> 624 | AB30: =(AB11+AB17+AB21+AB25)*$A$62 -> 624 | AC30: =(AC11+AC17+AC21+AC25)*$A$62 -> 624 | AD30: =(AD11+AD17+AD21+AD25)*$A$62 -> 624 | AE30: =(AE11+AE17+AE21+AE25)*$A$62 -> 638 | AF30: =(AF11+AF17+AF21+AF25)*$A$62 -> 638 | ... BZ30: =(BZ11+BZ17+BZ21+BZ25)*$A$62 -> 658 | CA30: =(CA11+CA17+CA21+CA25)*$A$72 -> 1316 | CB30: =(CB11+CB17+CB21+CB25)*$A$62 -> 658 | CC30: =(CC11+CC17+CC21+CC25)*$A$62 -> 658
A31: 👤 | B31: Mantenimento | M31: =-$A$64 -> -350 | N31: =-$A$64 -> -350 | O31: =-$A$64 -> -350 | P31: =-$A$64 -> -350 | Q31: =-$A$64 -> -350 | R31: =-$A$64 -> -350 | S31: =-$A$64 -> -350 | T31: =-$A$64 -> -350 | ... AD31: =-$A$64 -> -350 | AE31: -400 | AF31: -400 | AG31: -400 | AH31: -420 | AI31: -440 | AJ31: -460 | AK31: =AJ31 -> -460 | AL31: =AK31 -> -460 | AM31: =AL31 -> -460 | AN31: =AM31 -> -460 | AO31: =AN31 -> -460 | AP31: =AO31 -> -460 | AQ31: =AP31 -> -460 | AR31: =AQ31 -> -460 | ... CC31: =CB31 -> -460
B32: Prezzo magazzino | M32: =-A63 -> -5000
A33: Tasse bancarelle
A34: 📜 | B34: Tassa bancarella Kanemura | D34: =-$A$65 -> -25 | E34: =-$A$65 -> -25 | F34: =-$A$65 -> -25 | G34: =-$A$65 -> -25 | H34: =-$A$65 -> -25 | I34: =-$A$65 -> -25 | J34: =-$A$65 -> -25 | K34: =-$A$65 -> -25 | ... CC34: =-$A$65 -> -25
A35: 📜 | B35: Tassa bancarella Takamura | D35: =-$A$65 -> -25 | E35: =-$A$65 -> -25 | F35: =-$A$65 -> -25 | G35: =-$A$65 -> -25 | H35: =-$A$65 -> -25 | I35: =-$A$65 -> -25 | J35: =-$A$65 -> -25 | K35: =-$A$65 -> -25 | ... CC35: =-$A$65 -> -25
A36: 📜 | B36: Tassa bancarella Umihana | G36: =-$A$65 -> -25 | H36: =-$A$65 -> -25 | I36: =-$A$65 -> -25 | J36: =-$A$65 -> -25 | K36: =-$A$65 -> -25 | L36: =-$A$65 -> -25 | M36: =-$A$65 -> -25 | N36: =-$A$65 -> -25 | ... CC36: =-$A$65 -> -25
A37: ⭐️ | B37: Storia e Arte
A38: ⭐️ | B38: Modi di fare
A39: Assicurazione | D39: =-SUMIF(D11:D32, ">=0")*$A$69 -> -33 | E39: =-SUMIF(E11:E32, ">=0")*$A$69 -> -33 | F39: =-SUMIF(F11:F32, ">=0")*$A$69 -> -33 | G39: =-SUMIF(G11:G32, ">=0")*$A$69 -> -52.8 | H39: =-SUMIF(H11:H32, ">=0")*$A$69 -> -52.8 | I39: =-SUMIF(I11:I32, ">=0")*$A$69 -> -52.8 | J39: =-SUMIF(J11:J32, ">=0")*$A$69 -> -72.6 | K39: =-SUMIF(K11:K32, ">=0")*$A$69 -> -72.6 | ... CC39: =-SUMIF(CC11:CC32, ">=0")*$A$69 -> -118.44
BZ41: Burocrate | CA41: =1200 -> 1200 | CB41: =1200 -> 1200 | CC41: =1200 -> 1200
...

Sheet Zilla
F1: Zilla | H1: Aprile | I1: Maggio | J1: Giugno | K1: Luglio | L1: Agosto | M1: Settembre | N1: Ottobre | O1: Novembre | P1: Dicembre | Q1: Gennaio | R1: Febbraio | S1: Marzo | T1: Aprile | U1: Maggio | V1: Giugno | W1: Luglio | X1: Agosto | Y1: Settembre | Z1: Ottobre | AA1: Novembre | AB1: Dicembre | AC1: Gennaio | AD1: Febbraio | AE1: Marzo | AF1: Aprile | AG1: Maggio | AH1: Giugno | AI1: Luglio | AJ1: Agosto | AK1: Settembre | AL1: Ottobre | AM1: Novembre | AN1: Dicembre | AO1: Gennaio | AP1: Febbraio | AQ1: Marzo | AR1: Aprile | AS1: Maggio | AT1: Giugno | AU1: Luglio | AV1: Agosto | AW1: Settembre | AX1: Ottobre | AY1: Novembre | AZ1: Dicembre | BA1: Gennaio | BB1: Febbraio | BC1: Marzo | BD1: Aprile | BE1: Maggio | BF1: Giugno | BG1: Luglio | BH1: Agosto | BI1: Settembre | BJ1: Ottobre | BK1: Novembre | BL1: Dicembre | BM1: Gennaio | BN1: Febbraio | BO1: Marzo | BP1: Aprile | BQ1: Maggio | BR1: Giugno | BS1: Luglio | BT1: Agosto | BU1: Settembre | BV1: Ottobre | BW1: Novembre | BX1: Dicembre | BY1: Gennaio | BZ1: Febbraio | CA1: Marzo | CB1: Aprile | CC1: Maggio | CD1: Giugno | CE1: Luglio | CF1: Agosto | CG1: Settembre | CH1: Ottobre | CI1: Novembre | CJ1: Dicembre | CK1: Gennaio | CL1: Febbraio | CM1: Marzo | CN1: Aprile | CO1: Maggio | CP1: Giugno | CQ1: Luglio | CR1: Agosto | CS1: Settembre | CT1: Ottobre | CU1: Novembre | CV1: Dicembre
F2: Anno | H2: 1532 | I2: =H2+IF(I1="Gennaio",1,0) -> 1532 | J2: =I2+IF(J1="Gennaio",1,0) -> 1532 | K2: =J2+IF(K1="Gennaio",1,0) -> 1532 | L2: =K2+IF(L1="Gennaio",1,0) -> 1532 | M2: =L2+IF(M1="Gennaio",1,0) -> 1532 | N2: =M2+IF(N1="Gennaio",1,0) -> 1532 | O2: =N2+IF(O1="Gennaio",1,0) -> 1532 | P2: =O2+IF(P1="Gennaio",1,0) -> 1532 | ... CV2: =CU2+IF(CV1="Gennaio",1,0) -> 1539
F3: Mese in-game | H3: =G3+1 -> 1 | I3: =H3+1 -> 2 | J3: =I3+1 -> 3 | K3: =J3+1 -> 4 | L3: =K3+1 -> 5 | M3: =L3+1 -> 6 | N3: =M3+1 -> 7 | O3: =N3+1 -> 8 | ... CV3: =CU3+1 -> 93
B5: =MAX(H9:CG9) -> 4270.2543 | F5: AV | G5: =ABS(G70) -> 75 | H5: =ABS(H22+H70) -> 1850 | K5: =ABS(K29) -> 900 | M5: =ABS(M67) -> 1000 | N5: =ABS(N36) -> 900 | Q5: =ABS(Q51+Q67) -> 320 | R5: =ABS(R67) -> 30 | V5: =ABS(V70) -> 500 | AE5: =-AE71 -> 130 | AF5: =-AF51-(6900+500)-AF67 -> 4900 | AL5: =ABS(AL67+AL68) -> 15500 | AT5: 20600 | AU5: 3000
B6: =MIN(H9:CG9) -> -27089.946 | F6: NAV | H6: =SUM($G5:H5)+H8 -> 5602 | I6: =SUM($G5:I5)+I8 -> 6204 | J6: =SUM($G5:J5)+J8 -> 6732.6667 | K6: =SUM($G5:K5)+K8 -> 7549.8667 | L6: =SUM($G5:L5)+L8 -> 8330.4 | M6: =SUM($G5:M5)+M8 -> 9147.6 | N6: =SUM($G5:N5)+N8 -> 10180 | O6: =SUM($G5:O5)+O8 -> 11212.4 | ... CG6: =SUM($G5:CG5)+CG8 -> 109297.53
F8: Liquidi | G8: =SUM(G12:G1048576) -> 4925 | H8: =G8+SUM(H12:H1048576) -> 3677 | I8: =H8+SUM(I12:I1048576) -> 4279 | J8: =I8+SUM(J12:J1048576) -> 4807.6667 | K8: =J8+SUM(K12:K1048576) -> 4724.8667 | L8: =K8+SUM(L12:L1048576) -> 5505.4 | M8: =L8+SUM(M12:M1048576) -> 5322.6 | N8: =M8+SUM(N12:N1048576) -> 5455 | O8: =N8+SUM(O12:O1048576) -> 6487.4 | ... CG8: =CF8+SUM(CG12:CG1048576) -> 59592.526
F9: Profitto netto | H9: =H8-G8 -> -1248 | I9: =I8-H8 -> 602 | J9: =J8-I8 -> 528.66667 | K9: =K8-J8 -> -82.8 | L9: =L8-K8 -> 780.53333 | M9: =M8-L8 -> -182.8 | N9: =N8-M8 -> 132.4 | O9: =O8-N8 -> 1032.4 | ... CG9: =CG8-CF8 -> 4270.2543
F12: Cibo | H12: -250 | I12: -250 | J12: -250 | K12: -250 | L12: -250 | M12: -250 | N12: -250 | O12: -250 | P12: -250 | Q12: -250 | R12: -250 | S12: -250 | T12: -250 | U12: -250 | V12: -250 | W12: -250 | X12: -250 | Y12: -250 | Z12: -250 | AA12: -250 | AB12: -250 | AC12: -250 | AD12: -250 | AE12: -250 | AF12: -250 | AG12: -250 | AH12: -250 | AI12: -250 | AJ12: -250 | AK12: -250 | AL12: -250 | AM12: -250 | AN12: -250 | AO12: -250 | AP12: -250 | AQ12: -250 | AR12: -250 | AS12: -250 | AT12: -250 | AU12: -250 | AV12: -250 | AW12: -250 | AX12: -250 | AY12: -250 | AZ12: -250 | BA12: -250 | BB12: -250 | BC12: -250 | BD12: -250 | BE12: -250 | BF12: -250 | BG12: -250 | BH12: -250 | BI12: -250 | BJ12: -250 | BK12: -250 | BL12: -250 | BM12: -250 | BN12: -250 | BO12: -250 | BP12: -250 | BQ12: -250 | BR12: -250 | BS12: -250 | BT12: -250 | BU12: -250 | BV12: -250 | BW12: -250 | BX12: -250 | BY12: -250 | BZ12: -250 | CA12: -250 | CB12: -250 | CC12: -250 | CD12: -250 | CE12: -250 | CF12: -250 | CG12: -250
F13: Affitto | H13: -90 | I13: -90 | J13: -90 | K13: -90 | L13: -90 | M13: -90 | N13: -90 | O13: -90 | P13: -90 | Q13: -90 | R13: -90 | S13: -90 | T13: -90 | U13: -90 | V13: -90 | W13: -90 | X13: -90 | Y13: -90 | Z13: -90 | AA13: -90 | AB13: -90 | AC13: -90 | AD13: -90 | AE13: -90 | AF13: -90 | AG13: -90 | AH13: -90 | AI13: -90 | AJ13: -90 | AK13: -90 | AL13: -90 | AM13: -90 | AN13: -90 | AO13: -90 | AP13: -90 | AQ13: -90 | AR13: -90 | AS13: -90 | AT13: -90 | AU13: -90 | AV13: -90 | AW13: -90 | AX13: -90 | AY13: -90 | AZ13: -90 | BA13: -90 | BB13: -90 | BC13: -90 | BD13: -90 | BE13: -90 | BF13: -90 | BG13: -90 | BH13: -90 | BI13: -90 | BJ13: -90 | BK13: -90 | BL13: -90 | BM13: -90 | BN13: -90 | BO13: -90 | BP13: -90 | BQ13: -90 | BR13: -90 | BS13: -90 | BT13: -90 | BU13: -90 | BV13: -90 | BW13: -90 | BX13: -90 | BY13: -90 | BZ13: -90 | CA13: -90 | CB13: -90 | CC13: -90 | CD13: -90 | CE13: -90 | CF13: -90 | CG13: -90
E14: =COUNTA(B15:C66) -> 13 | F14: / 13 Permessi
F16: Tratta 1 (U-H-T)
F17: Tratta 1 (T-H-U)
F18: Mercante (Zilla) | H18: =$E$75 -> 1100 | I18: =$E$75 -> 1100 | J18: =$E$75 -> 1100 | K18: =$E$75 -> 1100 | L18: =$E$75 -> 1100 | M18: =$E$75 -> 1100 | N18: =$E$75 -> 1100 | O18: =$E$75 -> 1100 | ... CG18: =$E$75 -> 1100
E19: ⭐️ | F19: Apprendista mercante | Z19: =$E$75*$E$77*$E$78 -> 528 | AA19: =$E$75*$E$77*$E$78 -> 528 | AB19: =$E$75*$E$77*$E$78 -> 528 | AC19: =$E$75*$E$77*$E$78 -> 528 | AD19: =$E$75*$E$77*$E$78 -> 528 | AE19: =$E$75*$E$77*$E$78 -> 528 | AF19: =$E$75*$E$77*$E$78 -> 528 | AG19: =$E$75*$E$77*$E$78 -> 528 | ... CG19: =$E$75*$E$77*$E$78 -> 528
F20: salario | Z20: =-$E$76 -> -300 | AA20: =-$E$76 -> -300 | AB20: =-$E$76 -> -300 | AC20: =-$E$76 -> -300 | AD20: =-$E$76 -> -300 | AE20: =-$E$76 -> -300 | AF20: =-$E$76 -> -300 | AG20: =-$E$76 -> -300 | AH20: =-$E$76 -> -300 | AI20: -400 | AJ20: -400 | AK20: -400 | AL20: -400 | AM20: -400 | AN20: -400 | AO20: -400 | AP20: -400 | AQ20: -400 | AR20: -400 | AS20: -400 | AT20: -400 | AU20: -400 | AV20: -400 | AW20: -400 | AX20: -400 | AY20: -400 | AZ20: -400 | BA20: -400 | BB20: -400 | BC20: -400 | BD20: -400 | BE20: =BD20 -> -400 | BF20: =BE20 -> -400 | BG20: =BF20 -> -400 | BH20: =BG20 -> -400 | BI20: =BH20 -> -400 | BJ20: =BI20 -> -400 | BK20: =BJ20 -> -400 | BL20: =BK20 -> -400 | ... CG20: =CF20 -> -400
B21: 📜 | F21: Tassa rotta commerciale | H21: =-$E$80 -> -100 | I21: =-$E$80 -> -100 | J21: =-$E$80 -> -100 | K21: =-$E$80 -> -100 | L21: =-$E$80 -> -100 | M21: =-$E$80 -> -100 | N21: =-$E$80 -> -100 | O21: =-$E$80 -> -100 | ... CG21: =-$E$80 -> -100
F22: Carro, cavallo, barili | H22: -900
F23: =SUM(H17:CG22) -> 85680
F25: Tratta 2 (U-H-T)
K26: =$E$75*$E$77 -> 660 | L26: =$E$75*$E$77 -> 660 | M26: =$E$75*$E$77 -> 660 | N26: =$E$75*$E$77 -> 660 | O26: =$E$75*$E$77 -> 660 | P26: =$E$75*$E$77 -> 660 | Q26: =$E$75*$E$77 -> 660 | R26: =$E$75*$E$77 -> 660 | ... CG26: =$E$75*$E$77 -> 660
B27: 👤 | F27: Apprendista mercante | K27: =-$E$76 -> -300 | L27: =-$E$76 -> -300 | M27: =-$E$76 -> -300 | N27: =-$E$76 -> -300 | O27: =-$E$76 -> -300 | P27: =-$E$76 -> -300 | Q27: =-$E$76 -> -300 | R27: =-$E$76 -> -300 | ... AH27: =-$E$76 -> -300 | AI27: -400 | AJ27: -400 | AK27: =AJ27 -> -400 | AL27: =AK27 -> -400 | AM27: =AL27 -> -400 | AN27: =AM27 -> -400 | AO27: =AN27 -> -400 | AP27: =AO27 -> -400 | AQ27: =AP27 -> -400 | AR27: =AQ27 -> -400 | ... CG27: =CF27 -> -400
B28: 📜 | F28: Tassa rotta commerciale | K28: =-$E$80 -> -100 | L28: =-$E$80 -> -100 | M28: =-$E$80 -> -100 | N28: =-$E$80 -> -100 | O28: =-$E$80 -> -100 | P28: =-$E$80 -> -100 | Q28: =-$E$80 -> -100 | R28: =-$E$80 -> -100 | ... CG28: =-$E$80 -> -100
F29: Carro, cavallo, barili | K29: -900
F30: =SUM(H25:CG29) -> 13500
F32: Tratta 3 (K-H-U)
N33: =$E$75*$E$77 -> 660 | O33: =$E$75*$E$77 -> 660 | P33: =$E$75*$E$77 -> 660 | Q33: =$E$75*$E$77 -> 660 | R33: =$E$75*$E$77 -> 660 | S33: =$E$75*$E$77 -> 660 | T33: =$E$75*$E$77 -> 660 | U33: =$E$75*$E$77 -> 660 | ... CG33: =$E$75*$E$77 -> 660
B34: 👤 | F34: Apprendista mercante | N34: =-$E$76 -> -300 | O34: =-$E$76 -> -300 | P34: =-$E$76 -> -300 | Q34: =-$E$76 -> -300 | R34: =-$E$76 -> -300 | S34: =-$E$76 -> -300 | T34: =-$E$76 -> -300 | U34: =-$E$76 -> -300 | ... AH34: =-$E$76 -> -300 | AI34: -400 | AJ34: -400 | AK34: -400 | AL34: =AK34 -> -400 | AM34: =AL34 -> -400 | AN34: =AM34 -> -400 | AO34: =AN34 -> -400 | AP34: =AO34 -> -400 | AQ34: =AP34 -> -400 | AR34: =AQ34 -> -400 | AS34: =AR34 -> -400 | ... CG34: =CF34 -> -400
B35: 📜 | F35: Tassa rotta commerciale | N35: =-$E$80 -> -100 | O35: =-$E$80 -> -100 | P35: =-$E$80 -> -100 | Q35: =-$E$80 -> -100 | R35: =-$E$80 -> -100 | S35: =-$E$80 -> -100 | T35: =-$E$80 -> -100 | U35: =-$E$80 -> -100 | ... CG35: =-$E$80 -> -100
F36: Carro, cavallo, barili | N36: -900
F37: =SUM(H32:CG36) -> 12720
F39: Tratta 4 (K-H-U)
B41: 👤 | F41: Apprendista mercante | AU41: =$E$75*$E$77 -> 660 | AV41: =$E$75*$E$77 -> 660 | AW41: =$E$75*$E$77 -> 660 | AX41: =$E$75*$E$77 -> 660 | AY41: =$E$75*$E$77 -> 660 | AZ41: =$E$75*$E$77 -> 660 | BA41: =$E$75*$E$77 -> 660 | BB41: =$E$75*$E$77 -> 660 | ... CG41: =$E$75*$E$77 -> 660
B42: 📜 | F42: Tassa rotta commerciale | AU42: -390 | AV42: =AU42 -> -390 | AW42: =AV42 -> -390 | AX42: =AW42 -> -390 | AY42: =AX42 -> -390 | AZ42: =AY42 -> -390 | BA42: =AZ42 -> -390 | BB42: =BA42 -> -390 | BC42: =BB42 -> -390 | ... CG42: =CF42 -> -390
F43: Carro, cavallo, barili | AU43: =-$E$80 -> -100 | AV43: =-$E$80 -> -100 | AW43: =-$E$80 -> -100 | AX43: =-$E$80 -> -100 | AY43: =-$E$80 -> -100 | AZ43: =-$E$80 -> -100 | BA43: =-$E$80 -> -100 | BB43: =-$E$80 -> -100 | ... CG43: =-$E$80 -> -100
F44: =SUM(H39:CG43) -> 6630 | AT44: barca media | AU44: -3000
F46: Magazzini (rotte 1, 2, 3)
F48: Boost vendite | Q48: =(Q18+Q26+Q33)*$E$81 -> 484 | R48: =(R18+R26+R33)*$E$81 -> 484 | S48: =(S18+S26+S33)*$E$81 -> 484 | T48: =(T18+T26+T33)*$E$81 -> 484 | U48: =(U18+U26+U33)*$E$81 -> 484 | V48: =(V18+V26+V33)*$E$81 -> 484 | W48: =(W18+W26+W33)*$E$81 -> 484 | X48: =(X18+X26+X33)*$E$81 -> 484 | Y48: =(Y18+Y26+Y33)*$E$81 -> 484 | Z48: =(Z18+Z26+Z33+Z19)*$E$81 -> 589.6 | AA48: =(AA18+AA26+AA33+AA19)*$E$81 -> 589.6 | AB48: =(AB18+AB26+AB33+AB19)*$E$81 -> 589.6 | AC48: =(AC18+AC26+AC33+AC19)*$E$81 -> 589.6 | AD48: =(AD18+AD26+AD33+AD19)*$E$81 -> 589.6 | AE48: =(AE18+AE26+AE33+AE19)*$E$81 -> 589.6 | AF48: =(AF18+AF26+AF33+AF19)*$E$82 -> 1474 | AG48: =(AG18+AG26+AG33+AG19)*$E$82 -> 1474 | AH48: =(AH18+AH26+AH33+AH19)*$E$82 -> 1474 | AI48: =(AI18+AI26+AI33+AI19)*$E$82 -> 1474 | AJ48: =(AJ18+AJ26+AJ33+AJ19)*$E$82 -> 1474 | AK48: =(AK18+AK26+AK33+AK19)*$E$82 -> 1474 | AL48: =(AL18+AL26+AL33+AL19)*$E$82 -> 1474 | AM48: =(AM18+AM26+AM33+AM19)*$E$82 -> 1474 | ... AT48: =(AT18+AT26+AT33+AT19)*$E$82 -> 1474 | AU48: =(AU18+AU26+AU33+AU19+AU41)*$E$82 -> 1804 | AV48: =(AV18+AV26+AV33+AV19)*$E$82 -> 1474 | AW48: =(AW18+AW26+AW33+AW19)*$E$82 -> 1474 | AX48: =(AX18+AX26+AX33+AX19)*$E$82 -> 1474 | AY48: =(AY18+AY26+AY33+AY19)*$E$82 -> 1474 | AZ48: =(AZ18+AZ26+AZ33+AZ19)*$E$82 -> 1474 | BA48: =(BA18+BA26+BA33+BA19)*$E$82 -> 1474 | BB48: =(BB18+BB26+BB33+BB19)*$E$82 -> 1474 | BC48: =(BC18+BC26+BC33+BC19)*$E$82 -> 1474 | ... CG48: =(CG18+CG26+CG33+CG19)*$E$82 -> 1474
B49: 👤 | C49: 👤 | F49: Mantenimento | Q49: =-$E$84 -> -350 | R49: =-$E$84 -> -350 | S49: =-$E$84 -> -350 | T49: =-$E$84 -> -350 | U49: =-$E$84 -> -350 | V49: =-$E$84 -> -350 | W49: =-$E$84 -> -350 | X49: =-$E$84 -> -350 | ... AE49: =-$E$84 -> -350 | AF49: =-$E$84*2 -> -700 | AG49: =-$E$84*2 -> -700 | AH49: =-$E$84*2 -> -700 | AI49: =-$E$84*2 -> -700 | AJ49: =-$E$84*2 -> -700 | AK49: =-$E$84*2 -> -700 | AL49: =-$E$84*2 -> -700 | AM49: =-$E$84*2 -> -700 | ... CG49: =-$E$84*2 -> -700
P50: magazzino piccolo (venduto) | Q50: era 69 gold
B51: 📜 | F51: magazzino grande Umihana | AE51: magazzino grande | AF51: -12000
...

Sheet Vito
D1: Vito | F1: Aprile | G1: Maggio | H1: Giugno | I1: Luglio | J1: Agosto | K1: Settembre | L1: Ottobre | M1: Novembre | N1: Dicembre | O1: Gennaio | P1: Febbraio | Q1: Marzo | R1: Aprile | S1: Maggio | T1: Giugno | U1: Luglio | V1: Agosto | W1: Settembre | X1: Ottobre | Y1: Novembre | Z1: Dicembre | AA1: Gennaio | AB1: Febbraio | AC1: Marzo | AD1: Aprile | AE1: Maggio | AF1: Giugno | AG1: Luglio | AH1: Agosto | AI1: Settembre | AJ1: Ottobre | AK1: Novembre | AL1: Dicembre | AM1: Gennaio | AN1: Febbraio | AO1: Marzo | AP1: Aprile | AQ1: Maggio | AR1: Giugno | AS1: Luglio | AT1: Agosto | AU1: Settembre | AV1: Ottobre | AW1: Novembre | AX1: Dicembre | AY1: Gennaio | AZ1: Febbraio | BA1: Marzo | BB1: Aprile | BC1: Maggio | BD1: Giugno | BE1: Luglio | BF1: Agosto | BG1: Settembre | BH1: Ottobre | BI1: Novembre | BJ1: Dicembre | BK1: Gennaio | BL1: Febbraio | BM1: Marzo | BN1: Aprile | BO1: Maggio | BP1: Giugno | BQ1: Luglio | BR1: Agosto | BS1: Settembre | BT1: Ottobre | BU1: Novembre | BV1: Dicembre | BW1: Gennaio | BX1: Febbraio | BY1: Marzo | BZ1: Aprile | CA1: Maggio | CB1: Giugno | CC1: Luglio | CD1: Agosto | CE1: Settembre | CF1: Ottobre | CG1: Novembre | CH1: Dicembre | CI1: Gennaio | CJ1: Febbraio | CK1: Marzo | CL1: Aprile | CM1: Maggio | CN1: Giugno | CO1: Luglio | CP1: Agosto | CQ1: Settembre | CR1: Ottobre | CS1: Novembre | CT1: Dicembre
D2: Anno | F2: 1532 | G2: =F2+IF(G1="Gennaio",1,0) -> 1532 | H2: =G2+IF(H1="Gennaio",1,0) -> 1532 | I2: =H2+IF(I1="Gennaio",1,0) -> 1532 | J2: =I2+IF(J1="Gennaio",1,0) -> 1532 | K2: =J2+IF(K1="Gennaio",1,0) -> 1532 | L2: =K2+IF(L1="Gennaio",1,0) -> 1532 | M2: =L2+IF(M1="Gennaio",1,0) -> 1532 | N2: =M2+IF(N1="Gennaio",1,0) -> 1532 | ... CT2: =CS2+IF(CT1="Gennaio",1,0) -> 1539
D3: Mese in-game | F3: =E3+1 -> 1 | G3: =F3+1 -> 2 | H3: =G3+1 -> 3 | I3: =H3+1 -> 4 | J3: =I3+1 -> 5 | K3: =J3+1 -> 6 | L3: =K3+1 -> 7 | M3: =L3+1 -> 8 | ... CT3: =CS3+1 -> 93
AM4: prestito | AY4: prestito
C5: =MAX(F9:CE9) -> 4920 | D5: AV | O5: =ABS(O35) -> 350 | U5: =ABS(U34+U37) -> 800 | AM5: -5000 | AR5: =20 -> 20 | AY5: 5000
C6: =MIN(F9:CE9) -> -3990 | D6: NAV | F6: =SUM($E5:F5)+F8 -> 5223 | G6: =SUM($E5:G5)+G8 -> 5479 | H6: =SUM($E5:H5)+H8 -> 5774 | I6: =SUM($E5:I5)+I8 -> 6024 | J6: =SUM($E5:J5)+J8 -> 6304 | K6: =SUM($E5:K5)+K8 -> 6584 | L6: =SUM($E5:L5)+L8 -> 6864 | M6: =SUM($E5:M5)+M8 -> 7144 | ... CE6: =SUM($E5:CE5)+CE8 -> 60066
D8: Liquidi | E8: =SUM(E11:E1048576) -> 5000 | F8: =E8+SUM(F11:F1048576) -> 5223 | G8: =F8+SUM(G11:G1048576) -> 5479 | H8: =G8+SUM(H11:H1048576) -> 5774 | I8: =H8+SUM(I11:I1048576) -> 6024 | J8: =I8+SUM(J11:J1048576) -> 6304 | K8: =J8+SUM(K11:K1048576) -> 6584 | L8: =K8+SUM(L11:L1048576) -> 6864 | M8: =L8+SUM(M11:M1048576) -> 7144 | ... CE8: =CD8+SUM(CE11:CE1048576) -> 58896
D9: Profitto netto | F9: =F8-E8 -> 223 | G9: =G8-F8 -> 256 | H9: =H8-G8 -> 295 | I9: =I8-H8 -> 250 | J9: =J8-I8 -> 280 | K9: =K8-J8 -> 280 | L9: =L8-K8 -> 280 | M9: =M8-L8 -> 280 | ... CE9: =CE8-CD8 -> 4060
D12: Cibo | F12: 0 | G12: 0 | H12: 0 | I12: 0 | J12: 0 | K12: 0 | L12: 0 | M12: 0 | N12: 0 | O12: 0 | P12: 0 | Q12: 0 | R12: 0 | S12: 0 | T12: 0 | U12: 0 | V12: 0 | W12: 0 | X12: 0 | Y12: 0 | Z12: 0 | AA12: 0 | AB12: 0 | AC12: 0 | AD12: 0 | AE12: 0 | AF12: 0 | AG12: 0 | AH12: 0 | AI12: 0 | AJ12: 0 | AK12: 0 | AL12: 0 | AM12: 0 | AN12: 0 | AO12: 0 | AP12: 0 | AQ12: 0 | AR12: 0 | AS12: 0 | AT12: 0 | AU12: 0 | AV12: 0 | AW12: 0 | AX12: 0 | AY12: 0 | AZ12: 0 | BA12: 0 | BB12: 0 | BC12: 0 | BD12: 0 | BE12: 0 | BF12: 0 | BG12: 0 | BH12: 0 | BI12: 0 | BJ12: 0 | BK12: 0 | BL12: 0 | BM12: 0 | BN12: 0 | BO12: 0 | BP12: 0 | BQ12: 0 | BR12: 0 | BS12: 0 | BT12: 0 | BU12: 0 | BV12: 0 | BW12: 0 | BX12: 0 | BY12: 0 | BZ12: 0 | CA12: 0 | CB12: 0 | CC12: 0 | CD12: 0 | CE12: 0
D13: Affitto | F13: 0 | G13: 0 | H13: 0 | I13: 0 | J13: 0 | K13: 0 | L13: 0 | M13: 0 | N13: 0 | O13: 0 | P13: 0 | Q13: 0 | R13: 0 | S13: 0 | T13: 0 | U13: 0 | V13: 0 | W13: 0 | X13: 0 | Y13: 0 | Z13: 0 | AA13: 0 | AB13: 0 | AC13: 0 | AD13: 0 | AE13: 0 | AF13: 0 | AG13: 0 | AH13: 0 | AI13: 0 | AJ13: 0 | AK13: 0 | AL13: 0 | AM13: 0 | AN13: 0 | AO13: 0 | AP13: 0 | AQ13: 0 | AR13: 0 | AS13: 0 | AT13: 0 | AU13: 0 | AV13: 0 | AW13: 0 | AX13: 0 | AY13: 0 | AZ13: 0 | BA13: 0 | BB13: 0 | BC13: 0 | BD13: 0 | BE13: 0 | BF13: 0 | BG13: 0 | BH13: 0 | BI13: 0 | BJ13: 0 | BK13: 0 | BL13: 0 | BM13: 0 | BN13: 0 | BO13: 0 | BP13: 0 | BQ13: 0 | BR13: 0 | BS13: 0 | BT13: 0 | BU13: 0 | BV13: 0 | BW13: 0 | BX13: 0 | BY13: 0 | BZ13: 0 | CA13: 0 | CB13: 0 | CC13: 0 | CD13: 0 | CE13: 0
C14: =COUNTA(A15:B42) -> 4 | D14: Permessi
D16: Impiego
D17: Assistente
C18: ⭐️ | D18: Salario | I18: =$C$42 -> 280 | J18: =$C$42 -> 280 | K18: =$C$42 -> 280 | L18: =$C$42 -> 280 | M18: =$C$42 -> 280 | N18: =$C$42 -> 280 | O18: =$C$42 -> 280 | P18: =$C$42 -> 280 | ... CE18: =$C$42 -> 280
D21: Servizio Postale a Cavallo | AJ21: aiuto zilla | AO21: +3 | AU21: +2 | BZ21: 2
D22: vendite | AD22: 200 | AE22: =AD22 -> 200 | AF22: =AE22 -> 200 | AG22: =AF22 -> 200 | AH22: =AG22 -> 200 | AI22: =AH22 -> 200 | AJ22: 400 | AK22: =AJ22 -> 400 | AL22: =AK22 -> 400 | AM22: =AL22+3*100 -> 700 | AN22: =AM22 -> 700 | AO22: =AN22+AO21*300 -> 1600 | AP22: =AO22+AP21*300 -> 1600 | AQ22: =AP22+AQ21*300 -> 1600 | AR22: =AQ22+AR21*300 -> 1600 | AS22: =AR22+AS21*300 -> 1600 | AT22: =AS22+AT21*300 -> 1600 | AU22: =AT22+AU21*300 -> 2200 | AV22: =AU22 -> 2200 | AW22: =AV22 -> 2200 | AX22: =AW22 -> 2200 | AY22: =AX22 -> 2200 | AZ22: =AY22 -> 2200 | BA22: =AZ22 -> 2200 | BB22: =BA22 -> 2200 | BC22: =BB22 -> 2200 | ... BY22: =BX22 -> 2200 | BZ22: =BY22+BZ21*200 -> 2600 | CA22: =BZ22 -> 2600 | CB22: =CA22 -> 2600 | CC22: =CB22 -> 2600 | CD22: =CC22 -> 2600 | CE22: =CD22 -> 2600
B23: 📜 | D23: dipendente Kanemura | AD23: -330 | AE23: -330 | AF23: -330 | AG23: -330 | AH23: -330 | AI23: -330 | AJ23: -330 | AK23: -330 | AL23: -330 | AM23: -330 | AN23: -330 | AO23: -330 | AP23: -330 | AQ23: -330 | AR23: -330 | AS23: -330 | AT23: -330 | AU23: -330 | AV23: -330 | AW23: -330 | AX23: -330 | AY23: -330 | AZ23: -330 | BA23: -330 | BB23: -330 | BC23: -330 | BD23: -330 | BE23: -330 | BF23: -330 | BG23: -330 | BH23: -330 | BI23: -330 | BJ23: -330 | BK23: -330 | BL23: -330 | BM23: -330 | BN23: -330 | BO23: -330 | BP23: -330 | BQ23: -330 | BR23: -330 | BS23: -330 | BT23: -330 | BU23: -330 | BV23: -330 | BW23: -330 | BX23: -330 | BY23: -330 | BZ23: -330 | CA23: -330 | CB23: -330 | CC23: -330 | CD23: -330 | CE23: -330
B24: 📜 | D24: dipendente Takamura | AD24: -330 | AE24: -330 | AF24: -330 | AG24: -330 | AH24: -330 | AI24: -330 | AJ24: -330 | AK24: -330 | AL24: -330 | AM24: -330 | AN24: -330 | AO24: -330 | AP24: -330 | AQ24: -330 | AR24: -330 | AS24: -330 | AT24: -330 | AU24: -330 | AV24: -330 | AW24: -330 | AX24: -330 | AY24: -330 | AZ24: -330 | BA24: -330 | BB24: -330 | BC24: -330 | BD24: -330 | BE24: -330 | BF24: -330 | BG24: -330 | BH24: -330 | BI24: -330 | BJ24: -330 | BK24: -330 | BL24: -330 | BM24: -330 | BN24: -330 | BO24: -330 | BP24: -330 | BQ24: -330 | BR24: -330 | BS24: -330 | BT24: -330 | BU24: -330 | BV24: -330 | BW24: -330 | BX24: -330 | BY24: -330 | BZ24: -330 | CA24: -330 | CB24: -330 | CC24: -330 | CD24: -330 | CE24: -330
B25: 📜 | D25: dipendente Umihana | AD25: -330 | AE25: -330 | AF25: -330 | AG25: -330 | AH25: -330 | AI25: -330 | AJ25: -330 | AK25: -330 | AL25: -330 | AM25: -330 | AN25: -330 | AO25: -330 | AP25: -330 | AQ25: -330 | AR25: -330 | AS25: -330 | AT25: -330 | AU25: -330 | AV25: -330 | AW25: -330 | AX25: -330 | AY25: -330 | AZ25: -330 | BA25: -330 | BB25: -330 | BC25: -330 | BD25: -330 | BE25: -330 | BF25: -330 | BG25: -330 | BH25: -330 | BI25: -330 | BJ25: -330 | BK25: -330 | BL25: -330 | BM25: -330 | BN25: -330 | BO25: -330 | BP25: -330 | BQ25: -330 | BR25: -330 | BS25: -330 | BT25: -330 | BU25: -330 | BV25: -330 | BW25: -330 | BX25: -330 | BY25: -330 | BZ25: -330 | CA25: -330 | CB25: -330 | CC25: -330 | CD25: -330 | CE25: -330
B26: 📜 | D26: dipendente Kanemura | AS26: -330 | AT26: -330 | AU26: -330 | AV26: -330 | AW26: -330 | AX26: -330 | AY26: -330 | AZ26: -330 | BA26: -330 | BB26: -330 | BC26: -330 | BD26: -330 | BE26: -330 | BF26: -330 | BG26: -330 | BH26: -330 | BI26: -330 | BJ26: -330 | BK26: -330 | BL26: -330 | BM26: -330 | BN26: -330 | BO26: -330 | BP26: -330 | BQ26: -330 | BR26: -330 | BS26: -330 | BT26: -330 | BU26: -330 | BV26: -330 | BW26: -330 | BX26: -330 | BY26: -330 | BZ26: -330 | CA26: -330 | CB26: -330 | CC26: -330 | CD26: -330 | CE26: -330
D28: Impiego
D29: Cameriera (terminato)
D30: Salario | F30: 223 | G30: 256 | H30: 295
CD31: premio Daimyo | CE31: =10000/4 -> 2500
AO32: miglioramento business (1 bianco +300)
E33: Bottino di partenza | O33: anello della nobildonna della missione | U33: vestito | AF33: tip dalle amiche | AG33: -50 | AI33: info | AJ33: -30 | AL33: info | AM33: -70 | AO33: info | AP33: -30 | AQ33: katana 941 | AR33: -20
E34: 5000 | O34: -350 | U34: -600 | AI34: info | AJ34: -50
O35: 350 | AF35: Masanori | AG35: -120 | AO35: info covo pirati | AP35: 150
I36: bribe info | Q36: bribe info | U36: orecchini e fermaglio | AL36: prestito | AM36: 5000 | AX36: ritorno prestito | AY36: =-5000*1.03 -> -5150
I37: =-10*3 -> -30 | Q37: -50 | U37: -200
AO38: todo prestito 10 gold
C42: 280 | D42: salario

Sheet Kleit
D1: Kleit | F1: Aprile | G1: Maggio | H1: Giugno | I1: Luglio | J1: Agosto | K1: Settembre | L1: Ottobre | M1: Novembre | N1: Dicembre | O1: Gennaio | P1: Febbraio | Q1: Marzo | R1: Aprile | S1: Maggio | T1: Giugno | U1: Luglio | V1: Agosto | W1: Settembre | X1: Ottobre | Y1: Novembre | Z1: Dicembre | AA1: Gennaio | AB1: Febbraio | AC1: Marzo | AD1: Aprile | AE1: Maggio | AF1: Giugno | AG1: Luglio | AH1: Agosto | AI1: Settembre | AJ1: Ottobre | AK1: Novembre | AL1: Dicembre | AM1: Gennaio | AN1: Febbraio | AO1: Marzo | AP1: Aprile | AQ1: Maggio | AR1: Giugno | AS1: Luglio | AT1: Agosto | AU1: Settembre | AV1: Ottobre | AW1: Novembre | AX1: Dicembre | AY1: Gennaio | AZ1: Febbraio | BA1: Marzo | BB1: Aprile | BC1: Maggio | BD1: Giugno | BE1: Luglio | BF1: Agosto | BG1: Settembre | BH1: Ottobre | BI1: Novembre | BJ1: Dicembre | BK1: Gennaio | BL1: Febbraio | BM1: Marzo | BN1: Aprile | BO1: Maggio | BP1: Giugno | BQ1: Luglio | BR1: Agosto | BS1: Settembre | BT1: Ottobre | BU1: Novembre | BV1: Dicembre | BW1: Gennaio | BX1: Febbraio | BY1: Marzo | BZ1: Aprile | CA1: Maggio | CB1: Giugno | CC1: Luglio | CD1: Agosto | CE1: Settembre | CF1: Ottobre | CG1: Novembre | CH1: Dicembre | CI1: Gennaio | CJ1: Febbraio | CK1: Marzo | CL1: Aprile | CM1: Maggio | CN1: Giugno | CO1: Luglio | CP1: Agosto | CQ1: Settembre | CR1: Ottobre | CS1: Novembre | CT1: Dicembre
D2: Anno | F2: 1532 | G2: =F2+IF(G1="Gennaio",1,0) -> 1532 | H2: =G2+IF(H1="Gennaio",1,0) -> 1532 | I2: =H2+IF(I1="Gennaio",1,0) -> 1532 | J2: =I2+IF(J1="Gennaio",1,0) -> 1532 | K2: =J2+IF(K1="Gennaio",1,0) -> 1532 | L2: =K2+IF(L1="Gennaio",1,0) -> 1532 | M2: =L2+IF(M1="Gennaio",1,0) -> 1532 | N2: =M2+IF(N1="Gennaio",1,0) -> 1532 | ... CT2: =CS2+IF(CT1="Gennaio",1,0) -> 1539
